Workbook
Name 분류: #REF!

Sheet OKR 트랙킹
B2: 부터 | C2: 까지 | D2: 주별 | E2: B2C 매출 | F2: 총 광고비 | G2: 가입자 수 | H2: 지역 내 가입자 수 | I2: 신규 유저 | J2: 신규 유저(D30) | K2: B2C 총 신청 수 | L2: B2C 수거 완료 | M2: B2C 수거 실패 | N2: CAC | O2: 지역내 가입율 | P2: 서비스 이용 전환율 | Q2: 보정 이용 전환율 | R2: 수거 실패율 | S2: 객단가 | T2: 회원탈퇴수
B3: 46113 | C3: 46203 | D3: Q2 누적 | E3: =SUMIFS('전체 일별'!$BA:$BA,'전체 일별'!$B:$B,">="&$B3,'전체 일별'!$B:$B,"<="&$C3) -> 1819838798 | F3: =SUMIFS('전체 일별'!$L:$L,'전체 일별'!$B:$B,">="&$B3,'전체 일별'!$B:$B,"<="&$C3) -> 478822013 | G3: =SUMIFS('전체 일별'!$AQ:$AQ,'전체 일별'!$B:$B,">="&$B3,'전체 일별'!$B:$B,"<="&$C3) -> 43513 | H3: =SUMIFS('전체 일별'!$AR:$AR,'전체 일별'!$B:$B,">="&$B3,'전체 일별'!$B:$B,"<="&$C3) -> 40309 | I3: =SUMIFS('전체 일별'!$AJ:$AJ,'전체 일별'!$B:$B,">="&$B3,'전체 일별'!$B:$B,"<="&$C3) -> 21079 | J3: =SUMIFS('전체 일별'!$Z:$Z,'전체 일별'!$B:$B,">="&$B3,'전체 일별'!$B:$B,"<="&$C3) -> 14221 | K3: =SUMIFS('전체 일별'!$AL:$AL,'전체 일별'!$B:$B,">="&$B3,'전체 일별'!$B:$B,"<="&$C3) -> 189646 | L3: =SUMIFS('전체 일별'!$AO:$AO,'전체 일별'!$B:$B,">="&$B3,'전체 일별'!$B:$B,"<="&$C3) -> 140920 | M3: =SUMIFS('전체 일별'!$AP:$AP,'전체 일별'!$B:$B,">="&$B3,'전체 일별'!$B:$B,"<="&$C3) -> 3840 | N3: =F3/J3 -> 33670.066 | O3: =H3/G3 -> 0.92636683 | P3: =J3/H3 -> 0.35279962 | Q3: =J3/H3 -> 0.35279962 | R3: =M3/(L3+M3) -> 0.026526665 | S3: =E3/L3 -> 12913.985 | T3: =SUMIFS('전체 일별'!$BJ:$BJ,'전체 일별'!$B:$B,">="&$B3,'전체 일별'!$B:$B,"<="&$C3) -> 1596
B4: =C4-13 -> 46094 | C4: =B5-1 -> 46107 | D4: 회고 전주 | E4: =SUMIFS('전체 일별'!$BA:$BA,'전체 일별'!$B:$B,">="&$B4,'전체 일별'!$B:$B,"<="&$C4) -> 704039209 | F4: =SUMIFS('전체 일별'!$L:$L,'전체 일별'!$B:$B,">="&$B4,'전체 일별'!$B:$B,"<="&$C4) -> 200149872 | G4: =SUMIFS('전체 일별'!$AQ:$AQ,'전체 일별'!$B:$B,">="&$B4,'전체 일별'!$B:$B,"<="&$C4) -> 21080 | H4: =SUMIFS('전체 일별'!$AR:$AR,'전체 일별'!$B:$B,">="&$B4,'전체 일별'!$B:$B,"<="&$C4) -> 19028 | I4: =SUMIFS('전체 일별'!$AJ:$AJ,'전체 일별'!$B:$B,">="&$B4,'전체 일별'!$B:$B,"<="&$C4) -> 8448 | J4: =SUMIFS('전체 일별'!$Z:$Z,'전체 일별'!$B:$B,">="&$B4,'전체 일별'!$B:$B,"<="&$C4) -> 5986 | K4: =SUMIFS('전체 일별'!$AL:$AL,'전체 일별'!$B:$B,">="&$B4,'전체 일별'!$B:$B,"<="&$C4) -> 65718 | L4: =SUMIFS('전체 일별'!$AO:$AO,'전체 일별'!$B:$B,">="&$B4,'전체 일별'!$B:$B,"<="&$C4) -> 71339 | M4: =SUMIFS('전체 일별'!$AP:$AP,'전체 일별'!$B:$B,">="&$B4,'전체 일별'!$B:$B,"<="&$C4) -> 1393 | N4: =F4/J4 -> 33436.33 | O4: =H4/G4 -> 0.90265655 | P4: =J4/H4 -> 0.31458903 | Q4: =J4/H4 -> 0.31458903 | R4: =M4/(L4+M4) -> 0.019152505 | S4: =E4/L4 -> 9868.9246 | T4: =SUMIFS('전체 일별'!$BJ:$BJ,'전체 일별'!$B:$B,">="&$B4,'전체 일별'!$B:$B,"<="&$C4) -> 719
B5: =C5-13 -> 46108 | C5: 46121 | D5: 회고 주 | E5: =SUMIFS('전체 일별'!$BA:$BA,'전체 일별'!$B:$B,">="&$B5,'전체 일별'!$B:$B,"<="&$C5) -> 756110818 | F5: =SUMIFS('전체 일별'!$L:$L,'전체 일별'!$B:$B,">="&$B5,'전체 일별'!$B:$B,"<="&$C5) -> 200904729 | G5: =SUMIFS('전체 일별'!$AQ:$AQ,'전체 일별'!$B:$B,">="&$B5,'전체 일별'!$B:$B,"<="&$C5) -> 21244 | H5: =SUMIFS('전체 일별'!$AR:$AR,'전체 일별'!$B:$B,">="&$B5,'전체 일별'!$B:$B,"<="&$C5) -> 19540 | I5: =SUMIFS('전체 일별'!$AJ:$AJ,'전체 일별'!$B:$B,">="&$B5,'전체 일별'!$B:$B,"<="&$C5) -> 9138 | J5: =SUMIFS('전체 일별'!$Z:$Z,'전체 일별'!$B:$B,">="&$B5,'전체 일별'!$B:$B,"<="&$C5) -> 6728 | K5: =SUMIFS('전체 일별'!$AL:$AL,'전체 일별'!$B:$B,">="&$B5,'전체 일별'!$B:$B,"<="&$C5) -> 81706 | L5: =SUMIFS('전체 일별'!$AO:$AO,'전체 일별'!$B:$B,">="&$B5,'전체 일별'!$B:$B,"<="&$C5) -> 62320 | M5: =SUMIFS('전체 일별'!$AP:$AP,'전체 일별'!$B:$B,">="&$B5,'전체 일별'!$B:$B,"<="&$C5) -> 1633 | N5: =F5/J5 -> 29860.988 | O5: =H5/G5 -> 0.91978912 | P5: =J5/H5 -> 0.34431934 | Q5: =J5/H5 -> 0.34431934 | R5: =M5/(L5+M5) -> 0.025534377 | S5: =E5/L5 -> 12132.715 | T5: =SUMIFS('전체 일별'!$BJ:$BJ,'전체 일별'!$B:$B,">="&$B5,'전체 일별'!$B:$B,"<="&$C5) -> 749
B6: 2주 전 대비 | E6: =E5-E4 -> 52071609 | F6: =F5-F4 -> 754857 | G6: =G5-G4 -> 164 | H6: =H5-H4 -> 512 | I6: =I5-I4 -> 690 | J6: =J5-J4 -> 742 | K6: =K5-K4 -> 15988 | L6: =L5-L4 -> -9019 | ... T6: =T5-T4 -> 30
B8: *대비 값 항상 더블 체킹 필요
E10: 지표명 | F10: 입력값 | G10: 계산값
E11: Q2 시작일 | F11: =DATE(2026,4,1) -> 46113
E12: Q2 종료일 | F12: =DATE(2026,6,30) -> 46203
E13: 목표 인원 | F13: 70000
E14: 초록불 기준 비율 | F14: 0.7
E15: 현재 누적 신규 유저 | F15: =I3 -> 21079
E16: 오늘 날짜 | F16: =TODAY() -> 46144
E17: 경과 주수 | G17: =(F16-F11)/7 -> 4.4285714
E18: 잔여 주수 | G18: =(F12-F16)/7 -> 8.4285714
E19: 초록불 목표값 (명) | G19: =F13*F14 -> 49000
E20: 주당 현재 속도 (명/주) | G20: =F15/G17 -> 4759.7742
E21: 초록불 달성 필요 주당 속도 (명/주) | G21: =(G19-F15)/G18 -> 3312.661 | M21: `
E22: Q2 말 예상 누적 (명) | G22: =F15+(G20*G18) -> 61197.097
E23: 달성율 | G23: =F15/F13 -> 0.30112857
E24: 신호등 판정 | G24: =IF(F15>=G19,"🟢 초록",IF(G20>=G21,"🟢 초록","🔴 위험")) -> 🟢 초록

Sheet 전체 월별
B2: 부터 | C2: 까지 | D2: 월별 | E2: B2C 매출 | F2: 총 광고비 | G2: 앱 설치수 | H2: 가입자 수 | I2: 지역 내 가입자 수 | J2: 신규 유저 | K2: 신규 유저(D30) | L2: B2C 총 신청 수 | M2: B2C 수거 완료 수 | N2: B2C 수거 실패 수 | O2: CAC | P2: CAC(D30) | Q2: 지역내 가입율 | R2: 서비스 이용 전환율 | S2: 보정 이용 전환율 | T2: 수거 실패율 | U2: 객단가 | V2: D1 비율평균 | W2: D2 비율평균 | X2: D3 비율평균 | Y2: D7 비율평균 | Z2: D30 비율평균 | AA2: D1 예측 | AB2: D2 예측 | AC2: D3 예측 | AD2: D7 예측
B3: 45292 | C3: 45322 | D3: 24년 1월 | E3: =SUMIFS('전체 일별'!$BA:$BA,'전체 일별'!$B:$B,">="&$B3,'전체 일별'!$B:$B,"<="&$C3) -> 0 | F3: =SUMIFS('전체 일별'!$L:$L,'전체 일별'!$B:$B,">="&$B3,'전체 일별'!$B:$B,"<="&$C3) -> 11700897 | G3: =SUMIFS('전체 일별'!$O:$O,'전체 일별'!$B:$B,">="&$B3,'전체 일별'!$B:$B,"<="&$C3) -> 2808 | H3: =SUMIFS('전체 일별'!$AQ:$AQ,'전체 일별'!$B:$B,">="&$B3,'전체 일별'!$B:$B,"<="&$C3) -> 1686 | I3: =SUMIFS('전체 일별'!$AR:$AR,'전체 일별'!$B:$B,">="&$B3,'전체 일별'!$B:$B,"<="&$C3) -> 756 | J3: =SUMIFS('전체 일별'!$AJ:$AJ,'전체 일별'!$B:$B,">="&$B3,'전체 일별'!$B:$B,"<="&$C3) -> 363 | K3: =SUMIFS('전체 일별'!$Z:$Z,'전체 일별'!$B:$B,">="&$B3,'전체 일별'!$B:$B,"<="&$C3) -> 0 | L3: =SUMIFS('전체 일별'!$AL:$AL,'전체 일별'!$B:$B,">="&$B3,'전체 일별'!$B:$B,"<="&$C3) -> 0 | M3: =SUMIFS('전체 일별'!$AO:$AO,'전체 일별'!$B:$B,">="&$B3,'전체 일별'!$B:$B,"<="&$C3) -> 0 | N3: =IFERROR(SUMIFS('전체 일별'!$AP:$AP,'전체 일별'!$B:$B,">="&$B3,'전체 일별'!$B:$B,"<="&$C3),0) -> 0 | O3: =F3/J3 -> 32233.876 | P3: =IFERROR(F3/K3,0) -> 0 | Q3: =I3/H3 -> 0.44839858 | R3: =J3/I3 -> 0.48015873 | S3: =K3/I3 -> 0 | T3: =IFERROR(N3/(M3+N3),0) -> 0 | U3: =IFERROR(E3/M3,0) -> 0
B4: 45323 | C4: 45351 | D4: 24년 2월 | E4: =SUMIFS('전체 일별'!$BA:$BA,'전체 일별'!$B:$B,">="&$B4,'전체 일별'!$B:$B,"<="&$C4) -> 0 | F4: =SUMIFS('전체 일별'!$L:$L,'전체 일별'!$B:$B,">="&$B4,'전체 일별'!$B:$B,"<="&$C4) -> 7314530 | G4: =SUMIFS('전체 일별'!$O:$O,'전체 일별'!$B:$B,">="&$B4,'전체 일별'!$B:$B,"<="&$C4) -> 3286 | H4: =SUMIFS('전체 일별'!$AQ:$AQ,'전체 일별'!$B:$B,">="&$B4,'전체 일별'!$B:$B,"<="&$C4) -> 2069 | I4: =SUMIFS('전체 일별'!$AR:$AR,'전체 일별'!$B:$B,">="&$B4,'전체 일별'!$B:$B,"<="&$C4) -> 1069 | J4: =SUMIFS('전체 일별'!$AJ:$AJ,'전체 일별'!$B:$B,">="&$B4,'전체 일별'!$B:$B,"<="&$C4) -> 599 | K4: =SUMIFS('전체 일별'!$Z:$Z,'전체 일별'!$B:$B,">="&$B4,'전체 일별'!$B:$B,"<="&$C4) -> 0 | L4: =SUMIFS('전체 일별'!$AL:$AL,'전체 일별'!$B:$B,">="&$B4,'전체 일별'!$B:$B,"<="&$C4) -> 0 | M4: =SUMIFS('전체 일별'!$AO:$AO,'전체 일별'!$B:$B,">="&$B4,'전체 일별'!$B:$B,"<="&$C4) -> 0 | N4: =SUMIFS('전체 일별'!$AP:$AP,'전체 일별'!$B:$B,">="&$B4,'전체 일별'!$B:$B,"<="&$C4) -> 0 | O4: =F4/J4 -> 12211.235 | P4: =IFERROR(F4/K4,0) -> 0 | Q4: =I4/H4 -> 0.51667472 | R4: =J4/I4 -> 0.56033676 | S4: =K4/I4 -> 0 | T4: =IFERROR(N4/(M4+N4),0) -> 0 | U4: =IFERROR(E4/M4,0) -> 0
B5: 45352 | C5: 45382 | D5: 24년 3월 | E5: =SUMIFS('전체 일별'!$BA:$BA,'전체 일별'!$B:$B,">="&$B5,'전체 일별'!$B:$B,"<="&$C5) -> 0 | F5: =SUMIFS('전체 일별'!$L:$L,'전체 일별'!$B:$B,">="&$B5,'전체 일별'!$B:$B,"<="&$C5) -> 10521325 | G5: =SUMIFS('전체 일별'!$O:$O,'전체 일별'!$B:$B,">="&$B5,'전체 일별'!$B:$B,"<="&$C5) -> 3427 | H5: =SUMIFS('전체 일별'!$AQ:$AQ,'전체 일별'!$B:$B,">="&$B5,'전체 일별'!$B:$B,"<="&$C5) -> 2202 | I5: =SUMIFS('전체 일별'!$AR:$AR,'전체 일별'!$B:$B,">="&$B5,'전체 일별'!$B:$B,"<="&$C5) -> 1100 | J5: =SUMIFS('전체 일별'!$AJ:$AJ,'전체 일별'!$B:$B,">="&$B5,'전체 일별'!$B:$B,"<="&$C5) -> 585 | K5: =SUMIFS('전체 일별'!$Z:$Z,'전체 일별'!$B:$B,">="&$B5,'전체 일별'!$B:$B,"<="&$C5) -> 0 | L5: =SUMIFS('전체 일별'!$AL:$AL,'전체 일별'!$B:$B,">="&$B5,'전체 일별'!$B:$B,"<="&$C5) -> 0 | M5: =SUMIFS('전체 일별'!$AO:$AO,'전체 일별'!$B:$B,">="&$B5,'전체 일별'!$B:$B,"<="&$C5) -> 0 | N5: =SUMIFS('전체 일별'!$AP:$AP,'전체 일별'!$B:$B,">="&$B5,'전체 일별'!$B:$B,"<="&$C5) -> 97 | O5: =F5/J5 -> 17985.171 | P5: =IFERROR(F5/K5,0) -> 0 | Q5: =I5/H5 -> 0.49954587 | R5: =J5/I5 -> 0.53181818 | S5: =K5/I5 -> 0 | T5: =IFERROR(N5/(M5+N5),0) -> 1 | U5: =IFERROR(E5/M5,0) -> 0
B6: 45383 | C6: 45412 | D6: 24년 4월 | E6: =SUMIFS('전체 일별'!$BA:$BA,'전체 일별'!$B:$B,">="&$B6,'전체 일별'!$B:$B,"<="&$C6) -> 0 | F6: =SUMIFS('전체 일별'!$L:$L,'전체 일별'!$B:$B,">="&$B6,'전체 일별'!$B:$B,"<="&$C6) -> 9120550 | G6: =SUMIFS('전체 일별'!$O:$O,'전체 일별'!$B:$B,">="&$B6,'전체 일별'!$B:$B,"<="&$C6) -> 3562 | H6: =SUMIFS('전체 일별'!$AQ:$AQ,'전체 일별'!$B:$B,">="&$B6,'전체 일별'!$B:$B,"<="&$C6) -> 2242 | I6: =SUMIFS('전체 일별'!$AR:$AR,'전체 일별'!$B:$B,">="&$B6,'전체 일별'!$B:$B,"<="&$C6) -> 1355 | J6: =SUMIFS('전체 일별'!$AJ:$AJ,'전체 일별'!$B:$B,">="&$B6,'전체 일별'!$B:$B,"<="&$C6) -> 600 | K6: =SUMIFS('전체 일별'!$Z:$Z,'전체 일별'!$B:$B,">="&$B6,'전체 일별'!$B:$B,"<="&$C6) -> 0 | L6: =SUMIFS('전체 일별'!$AL:$AL,'전체 일별'!$B:$B,">="&$B6,'전체 일별'!$B:$B,"<="&$C6) -> 0 | M6: =SUMIFS('전체 일별'!$AO:$AO,'전체 일별'!$B:$B,">="&$B6,'전체 일별'!$B:$B,"<="&$C6) -> 0 | N6: =SUMIFS('전체 일별'!$AP:$AP,'전체 일별'!$B:$B,">="&$B6,'전체 일별'!$B:$B,"<="&$C6) -> 230 | O6: =F6/J6 -> 15200.917 | P6: =IFERROR(F6/K6,0) -> 0 | Q6: =I6/H6 -> 0.6043711 | R6: =J6/I6 -> 0.44280443 | S6: =K6/I6 -> 0 | T6: =IFERROR(N6/(M6+N6),0) -> 1 | U6: =IFERROR(E6/M6,0) -> 0
B7: 45413 | C7: 45443 | D7: 24년 5월 | E7: =SUMIFS('전체 일별'!$BA:$BA,'전체 일별'!$B:$B,">="&$B7,'전체 일별'!$B:$B,"<="&$C7) -> 28515894 | F7: =SUMIFS('전체 일별'!$L:$L,'전체 일별'!$B:$B,">="&$B7,'전체 일별'!$B:$B,"<="&$C7) -> 12320320 | G7: =SUMIFS('전체 일별'!$O:$O,'전체 일별'!$B:$B,">="&$B7,'전체 일별'!$B:$B,"<="&$C7) -> 6389 | H7: =SUMIFS('전체 일별'!$AQ:$AQ,'전체 일별'!$B:$B,">="&$B7,'전체 일별'!$B:$B,"<="&$C7) -> 3787 | I7: =SUMIFS('전체 일별'!$AR:$AR,'전체 일별'!$B:$B,">="&$B7,'전체 일별'!$B:$B,"<="&$C7) -> 2170 | J7: =SUMIFS('전체 일별'!$AJ:$AJ,'전체 일별'!$B:$B,">="&$B7,'전체 일별'!$B:$B,"<="&$C7) -> 864 | K7: =SUMIFS('전체 일별'!$Z:$Z,'전체 일별'!$B:$B,">="&$B7,'전체 일별'!$B:$B,"<="&$C7) -> 0 | L7: =SUMIFS('전체 일별'!$AL:$AL,'전체 일별'!$B:$B,">="&$B7,'전체 일별'!$B:$B,"<="&$C7) -> 3635 | M7: =SUMIFS('전체 일별'!$AO:$AO,'전체 일별'!$B:$B,">="&$B7,'전체 일별'!$B:$B,"<="&$C7) -> 3077 | N7: =SUMIFS('전체 일별'!$AP:$AP,'전체 일별'!$B:$B,">="&$B7,'전체 일별'!$B:$B,"<="&$C7) -> 316 | O7: =F7/J7 -> 14259.63 | P7: =IFERROR(F7/K7,0) -> 0 | Q7: =I7/H7 -> 0.57301294 | R7: =J7/I7 -> 0.39815668 | S7: =K7/I7 -> 0 | T7: =IFERROR(N7/(M7+N7),0) -> 0.093132921 | U7: =IFERROR(E7/M7,0) -> 9267.4339
B8: 45444 | C8: 45473 | D8: 24년 6월 | E8: =SUMIFS('전체 일별'!$BA:$BA,'전체 일별'!$B:$B,">="&$B8,'전체 일별'!$B:$B,"<="&$C8) -> 75514970 | F8: =SUMIFS('전체 일별'!$L:$L,'전체 일별'!$B:$B,">="&$B8,'전체 일별'!$B:$B,"<="&$C8) -> 18389466 | G8: =SUMIFS('전체 일별'!$O:$O,'전체 일별'!$B:$B,">="&$B8,'전체 일별'!$B:$B,"<="&$C8) -> 10975 | H8: =SUMIFS('전체 일별'!$AQ:$AQ,'전체 일별'!$B:$B,">="&$B8,'전체 일별'!$B:$B,"<="&$C8) -> 6164 | I8: =SUMIFS('전체 일별'!$AR:$AR,'전체 일별'!$B:$B,">="&$B8,'전체 일별'!$B:$B,"<="&$C8) -> 4385 | J8: =SUMIFS('전체 일별'!$AJ:$AJ,'전체 일별'!$B:$B,">="&$B8,'전체 일별'!$B:$B,"<="&$C8) -> 1373 | K8: =SUMIFS('전체 일별'!$Z:$Z,'전체 일별'!$B:$B,">="&$B8,'전체 일별'!$B:$B,"<="&$C8) -> 0 | L8: =SUMIFS('전체 일별'!$AL:$AL,'전체 일별'!$B:$B,">="&$B8,'전체 일별'!$B:$B,"<="&$C8) -> 9975 | M8: =SUMIFS('전체 일별'!$AO:$AO,'전체 일별'!$B:$B,">="&$B8,'전체 일별'!$B:$B,"<="&$C8) -> 8971 | N8: =SUMIFS('전체 일별'!$AP:$AP,'전체 일별'!$B:$B,">="&$B8,'전체 일별'!$B:$B,"<="&$C8) -> 366 | O8: =F8/J8 -> 13393.639 | P8: =IFERROR(F8/K8,0) -> 0 | Q8: =I8/H8 -> 0.71138871 | R8: =J8/I8 -> 0.31311288 | S8: =K8/I8 -> 0 | T8: =IFERROR(N8/(M8+N8),0) -> 0.039198886 | U8: =IFERROR(E8/M8,0) -> 8417.6758
B9: 45474 | C9: 45504 | D9: 24년 7월 | E9: =SUMIFS('전체 일별'!$BA:$BA,'전체 일별'!$B:$B,">="&$B9,'전체 일별'!$B:$B,"<="&$C9) -> 101076234 | F9: =SUMIFS('전체 일별'!$L:$L,'전체 일별'!$B:$B,">="&$B9,'전체 일별'!$B:$B,"<="&$C9) -> 24058665 | G9: =SUMIFS('전체 일별'!$O:$O,'전체 일별'!$B:$B,">="&$B9,'전체 일별'!$B:$B,"<="&$C9) -> 12251 | H9: =SUMIFS('전체 일별'!$AQ:$AQ,'전체 일별'!$B:$B,">="&$B9,'전체 일별'!$B:$B,"<="&$C9) -> 7262 | I9: =SUMIFS('전체 일별'!$AR:$AR,'전체 일별'!$B:$B,">="&$B9,'전체 일별'!$B:$B,"<="&$C9) -> 5617 | J9: =SUMIFS('전체 일별'!$AJ:$AJ,'전체 일별'!$B:$B,">="&$B9,'전체 일별'!$B:$B,"<="&$C9) -> 1843 | K9: =SUMIFS('전체 일별'!$Z:$Z,'전체 일별'!$B:$B,">="&$B9,'전체 일별'!$B:$B,"<="&$C9) -> 888 | L9: =SUMIFS('전체 일별'!$AL:$AL,'전체 일별'!$B:$B,">="&$B9,'전체 일별'!$B:$B,"<="&$C9) -> 12915 | M9: =SUMIFS('전체 일별'!$AO:$AO,'전체 일별'!$B:$B,">="&$B9,'전체 일별'!$B:$B,"<="&$C9) -> 12006 | N9: =SUMIFS('전체 일별'!$AP:$AP,'전체 일별'!$B:$B,">="&$B9,'전체 일별'!$B:$B,"<="&$C9) -> 375 | O9: =F9/J9 -> 13054.078 | P9: =IFERROR(F9/K9,0) -> 27093.091 | Q9: =I9/H9 -> 0.77347838 | R9: =J9/I9 -> 0.32811109 | S9: =K9/I9 -> 0.15809151 | T9: =IFERROR(N9/(M9+N9),0) -> 0.030288345 | U9: =IFERROR(E9/M9,0) -> 8418.8101
B10: 45505 | C10: 45535 | D10: 24년 8월 | E10: =SUMIFS('전체 일별'!$BA:$BA,'전체 일별'!$B:$B,">="&$B10,'전체 일별'!$B:$B,"<="&$C10) -> 135260127 | F10: =SUMIFS('전체 일별'!$L:$L,'전체 일별'!$B:$B,">="&$B10,'전체 일별'!$B:$B,"<="&$C10) -> 24930196 | G10: =SUMIFS('전체 일별'!$O:$O,'전체 일별'!$B:$B,">="&$B10,'전체 일별'!$B:$B,"<="&$C10) -> 12794 | H10: =SUMIFS('전체 일별'!$AQ:$AQ,'전체 일별'!$B:$B,">="&$B10,'전체 일별'!$B:$B,"<="&$C10) -> 7789 | I10: =SUMIFS('전체 일별'!$AR:$AR,'전체 일별'!$B:$B,">="&$B10,'전체 일별'!$B:$B,"<="&$C10) -> 6256 | J10: =SUMIFS('전체 일별'!$AJ:$AJ,'전체 일별'!$B:$B,">="&$B10,'전체 일별'!$B:$B,"<="&$C10) -> 2371 | K10: =SUMIFS('전체 일별'!$Z:$Z,'전체 일별'!$B:$B,">="&$B10,'전체 일별'!$B:$B,"<="&$C10) -> 1793 | L10: =SUMIFS('전체 일별'!$AL:$AL,'전체 일별'!$B:$B,">="&$B10,'전체 일별'!$B:$B,"<="&$C10) -> 16580 | M10: =SUMIFS('전체 일별'!$AO:$AO,'전체 일별'!$B:$B,">="&$B10,'전체 일별'!$B:$B,"<="&$C10) -> 15373 | N10: =SUMIFS('전체 일별'!$AP:$AP,'전체 일별'!$B:$B,">="&$B10,'전체 일별'!$B:$B,"<="&$C10) -> 576 | O10: =F10/J10 -> 10514.633 | P10: =IFERROR(F10/K10,0) -> 13904.181 | Q10: =I10/H10 -> 0.80318398 | R10: =J10/I10 -> 0.37899616 | S10: =K10/I10 -> 0.28660486 | T10: =IFERROR(N10/(M10+N10),0) -> 0.036115117 | U10: =IFERROR(E10/M10,0) -> 8798.5512
B11: 45536 | C11: 45565 | D11: 24년 9월 | E11: =SUMIFS('전체 일별'!$BA:$BA,'전체 일별'!$B:$B,">="&$B11,'전체 일별'!$B:$B,"<="&$C11) -> 140546910 | F11: =SUMIFS('전체 일별'!$L:$L,'전체 일별'!$B:$B,">="&$B11,'전체 일별'!$B:$B,"<="&$C11) -> 21956951 | G11: =SUMIFS('전체 일별'!$O:$O,'전체 일별'!$B:$B,">="&$B11,'전체 일별'!$B:$B,"<="&$C11) -> 11022 | H11: =SUMIFS('전체 일별'!$AQ:$AQ,'전체 일별'!$B:$B,">="&$B11,'전체 일별'!$B:$B,"<="&$C11) -> 6735 | I11: =SUMIFS('전체 일별'!$AR:$AR,'전체 일별'!$B:$B,">="&$B11,'전체 일별'!$B:$B,"<="&$C11) -> 5190 | J11: =SUMIFS('전체 일별'!$AJ:$AJ,'전체 일별'!$B:$B,">="&$B11,'전체 일별'!$B:$B,"<="&$C11) -> 1853 | K11: =SUMIFS('전체 일별'!$Z:$Z,'전체 일별'!$B:$B,">="&$B11,'전체 일별'!$B:$B,"<="&$C11) -> 1516 | L11: =SUMIFS('전체 일별'!$AL:$AL,'전체 일별'!$B:$B,">="&$B11,'전체 일별'!$B:$B,"<="&$C11) -> 17078 | M11: =SUMIFS('전체 일별'!$AO:$AO,'전체 일별'!$B:$B,">="&$B11,'전체 일별'!$B:$B,"<="&$C11) -> 15904 | N11: =SUMIFS('전체 일별'!$AP:$AP,'전체 일별'!$B:$B,">="&$B11,'전체 일별'!$B:$B,"<="&$C11) -> 538 | O11: =F11/J11 -> 11849.407 | P11: =IFERROR(F11/K11,0) -> 14483.477 | Q11: =I11/H11 -> 0.77060134 | R11: =J11/I11 -> 0.35703276 | S11: =K11/I11 -> 0.29210019 | T11: =IFERROR(N11/(M11+N11),0) -> 0.03272108 | U11: =IFERROR(E11/M11,0) -> 8837.2051 | V11: =AVERAGEIFS('전체 일별'!$AF:$AF,'전체 일별'!$B:$B,">="&$B11,'전체 일별'!$B:$B,"<="&$C11) -> 0.10272333 | W11: =AVERAGEIFS('전체 일별'!$AB:$AB,'전체 일별'!$B:$B,">="&$B11,'전체 일별'!$B:$B,"<="&$C11) -> 0.13875333 | X11: =AVERAGEIFS('전체 일별'!$X:$X,'전체 일별'!$B:$B,">="&$B11,'전체 일별'!$B:$B,"<="&$C11) -> 0.16165333 | Y11: =AVERAGEIFS('전체 일별'!$BG:$BG,'전체 일별'!$B:$B,">="&$B11,'전체 일별'!$B:$B,"<="&$C11) -> 0.21393 | Z11: =AVERAGEIFS('전체 일별'!$BI:$BI,'전체 일별'!$B:$B,">="&$B11,'전체 일별'!$B:$B,"<="&$C11) -> 0.29242
B12: 45566 | C12: 45596 | D12: 24년 10월 | E12: =SUMIFS('전체 일별'!$BA:$BA,'전체 일별'!$B:$B,">="&$B12,'전체 일별'!$B:$B,"<="&$C12) -> 169223088 | F12: =SUMIFS('전체 일별'!$L:$L,'전체 일별'!$B:$B,">="&$B12,'전체 일별'!$B:$B,"<="&$C12) -> 30825543 | G12: =SUMIFS('전체 일별'!$O:$O,'전체 일별'!$B:$B,">="&$B12,'전체 일별'!$B:$B,"<="&$C12) -> 14758 | H12: =SUMIFS('전체 일별'!$AQ:$AQ,'전체 일별'!$B:$B,">="&$B12,'전체 일별'!$B:$B,"<="&$C12) -> 7971 | I12: =SUMIFS('전체 일별'!$AR:$AR,'전체 일별'!$B:$B,">="&$B12,'전체 일별'!$B:$B,"<="&$C12) -> 6037 | J12: =SUMIFS('전체 일별'!$AJ:$AJ,'전체 일별'!$B:$B,">="&$B12,'전체 일별'!$B:$B,"<="&$C12) -> 1959 | K12: =SUMIFS('전체 일별'!$Z:$Z,'전체 일별'!$B:$B,">="&$B12,'전체 일별'!$B:$B,"<="&$C12) -> 1570 | L12: =SUMIFS('전체 일별'!$AL:$AL,'전체 일별'!$B:$B,">="&$B12,'전체 일별'!$B:$B,"<="&$C12) -> 19134 | M12: =SUMIFS('전체 일별'!$AO:$AO,'전체 일별'!$B:$B,">="&$B12,'전체 일별'!$B:$B,"<="&$C12) -> 18201 | N12: =SUMIFS('전체 일별'!$AP:$AP,'전체 일별'!$B:$B,">="&$B12,'전체 일별'!$B:$B,"<="&$C12) -> 513 | O12: =F12/J12 -> 15735.346 | P12: =IFERROR(F12/K12,0) -> 19634.104 | Q12: =I12/H12 -> 0.75737047 | R12: =J12/I12 -> 0.32449892 | S12: =K12/I12 -> 0.26006295 | T12: =IFERROR(N12/(M12+N12),0) -> 0.027412632 | U12: =IFERROR(E12/M12,0) -> 9297.461 | V12: =AVERAGEIFS('전체 일별'!$AF:$AF,'전체 일별'!$B:$B,">="&$B12,'전체 일별'!$B:$B,"<="&$C12) -> 0.085548387 | W12: =AVERAGEIFS('전체 일별'!$AB:$AB,'전체 일별'!$B:$B,">="&$B12,'전체 일별'!$B:$B,"<="&$C12) -> 0.12195806 | X12: =AVERAGEIFS('전체 일별'!$X:$X,'전체 일별'!$B:$B,">="&$B12,'전체 일별'!$B:$B,"<="&$C12) -> 0.14167742 | Y12: =AVERAGEIFS('전체 일별'!$BG:$BG,'전체 일별'!$B:$B,">="&$B12,'전체 일별'!$B:$B,"<="&$C12) -> 0.19582903 | Z12: =AVERAGEIFS('전체 일별'!$BI:$BI,'전체 일별'!$B:$B,">="&$B12,'전체 일별'!$B:$B,"<="&$C12) -> 0.2617129
B13: 45597 | C13: 45626 | D13: 24년 11월 | E13: =SUMIFS('전체 일별'!$BA:$BA,'전체 일별'!$B:$B,">="&$B13,'전체 일별'!$B:$B,"<="&$C13) -> 173677002 | F13: =SUMIFS('전체 일별'!$L:$L,'전체 일별'!$B:$B,">="&$B13,'전체 일별'!$B:$B,"<="&$C13) -> 36112483 | G13: =SUMIFS('전체 일별'!$O:$O,'전체 일별'!$B:$B,">="&$B13,'전체 일별'!$B:$B,"<="&$C13) -> 17492 | H13: =SUMIFS('전체 일별'!$AQ:$AQ,'전체 일별'!$B:$B,">="&$B13,'전체 일별'!$B:$B,"<="&$C13) -> 8902 | I13: =SUMIFS('전체 일별'!$AR:$AR,'전체 일별'!$B:$B,">="&$B13,'전체 일별'!$B:$B,"<="&$C13) -> 5937 | J13: =SUMIFS('전체 일별'!$AJ:$AJ,'전체 일별'!$B:$B,">="&$B13,'전체 일별'!$B:$B,"<="&$C13) -> 1876 | K13: =SUMIFS('전체 일별'!$Z:$Z,'전체 일별'!$B:$B,">="&$B13,'전체 일별'!$B:$B,"<="&$C13) -> 1615 | L13: =SUMIFS('전체 일별'!$AL:$AL,'전체 일별'!$B:$B,">="&$B13,'전체 일별'!$B:$B,"<="&$C13) -> 18971 | M13: =SUMIFS('전체 일별'!$AO:$AO,'전체 일별'!$B:$B,">="&$B13,'전체 일별'!$B:$B,"<="&$C13) -> 17993 | N13: =SUMIFS('전체 일별'!$AP:$AP,'전체 일별'!$B:$B,">="&$B13,'전체 일별'!$B:$B,"<="&$C13) -> 431 | O13: =F13/J13 -> 19249.724 | P13: =IFERROR(F13/K13,0) -> 22360.671 | Q13: =I13/H13 -> 0.66692878 | R13: =J13/I13 -> 0.3159845 | S13: =K13/I13 -> 0.27202291 | T13: =IFERROR(N13/(M13+N13),0) -> 0.0233934 | U13: =IFERROR(E13/M13,0) -> 9652.4761 | V13: =AVERAGEIFS('전체 일별'!$AF:$AF,'전체 일별'!$B:$B,">="&$B13,'전체 일별'!$B:$B,"<="&$C13) -> 0.093366667 | W13: =AVERAGEIFS('전체 일별'!$AB:$AB,'전체 일별'!$B:$B,">="&$B13,'전체 일별'!$B:$B,"<="&$C13) -> 0.12530667 | X13: =AVERAGEIFS('전체 일별'!$X:$X,'전체 일별'!$B:$B,">="&$B13,'전체 일별'!$B:$B,"<="&$C13) -> 0.1484 | Y13: =AVERAGEIFS('전체 일별'!$BG:$BG,'전체 일별'!$B:$B,">="&$B13,'전체 일별'!$B:$B,"<="&$C13) -> 0.19816667 | Z13: =AVERAGEIFS('전체 일별'!$BI:$BI,'전체 일별'!$B:$B,">="&$B13,'전체 일별'!$B:$B,"<="&$C13) -> 0.27430333
B14: 45627 | C14: 45657 | D14: 24년 12월 | E14: =SUMIFS('전체 일별'!$BA:$BA,'전체 일별'!$B:$B,">="&$B14,'전체 일별'!$B:$B,"<="&$C14) -> 185428612 | F14: =SUMIFS('전체 일별'!$L:$L,'전체 일별'!$B:$B,">="&$B14,'전체 일별'!$B:$B,"<="&$C14) -> 48497027 | G14: =SUMIFS('전체 일별'!$O:$O,'전체 일별'!$B:$B,">="&$B14,'전체 일별'!$B:$B,"<="&$C14) -> 22584 | H14: =SUMIFS('전체 일별'!$AQ:$AQ,'전체 일별'!$B:$B,">="&$B14,'전체 일별'!$B:$B,"<="&$C14) -> 12037 | I14: =SUMIFS('전체 일별'!$AR:$AR,'전체 일별'!$B:$B,">="&$B14,'전체 일별'!$B:$B,"<="&$C14) -> 7642 | J14: =SUMIFS('전체 일별'!$AJ:$AJ,'전체 일별'!$B:$B,">="&$B14,'전체 일별'!$B:$B,"<="&$C14) -> 2545 | K14: =SUMIFS('전체 일별'!$Z:$Z,'전체 일별'!$B:$B,">="&$B14,'전체 일별'!$B:$B,"<="&$C14) -> 2161 | L14: =SUMIFS('전체 일별'!$AL:$AL,'전체 일별'!$B:$B,">="&$B14,'전체 일별'!$B:$B,"<="&$C14) -> 21004 | M14: =SUMIFS('전체 일별'!$AO:$AO,'전체 일별'!$B:$B,">="&$B14,'전체 일별'!$B:$B,"<="&$C14) -> 19803 | N14: =SUMIFS('전체 일별'!$AP:$AP,'전체 일별'!$B:$B,">="&$B14,'전체 일별'!$B:$B,"<="&$C14) -> 511 | O14: =F14/J14 -> 19055.806 | P14: =IFERROR(F14/K14,0) -> 22441.938 | Q14: =I14/H14 -> 0.6348758 | R14: =J14/I14 -> 0.333028 | S14: =K14/I14 -> 0.28277938 | T14: =IFERROR(N14/(M14+N14),0) -> 0.025155065 | U14: =IFERROR(E14/M14,0) -> 9363.6627 | V14: =AVERAGEIFS('전체 일별'!$AF:$AF,'전체 일별'!$B:$B,">="&$B14,'전체 일별'!$B:$B,"<="&$C14) -> 0.10032258 | W14: =AVERAGEIFS('전체 일별'!$AB:$AB,'전체 일별'!$B:$B,">="&$B14,'전체 일별'!$B:$B,"<="&$C14) -> 0.13448387 | X14: =AVERAGEIFS('전체 일별'!$X:$X,'전체 일별'!$B:$B,">="&$B14,'전체 일별'!$B:$B,"<="&$C14) -> 0.15321613 | Y14: =AVERAGEIFS('전체 일별'!$BG:$BG,'전체 일별'!$B:$B,">="&$B14,'전체 일별'!$B:$B,"<="&$C14) -> 0.2108129 | Z14: =AVERAGEIFS('전체 일별'!$BI:$BI,'전체 일별'!$B:$B,">="&$B14,'전체 일별'!$B:$B,"<="&$C14) -> 0.28017742
B15: 45658 | C15: 45688 | D15: 25년 1월 | E15: =SUMIFS('전체 일별'!$BA:$BA,'전체 일별'!$B:$B,">="&$B15,'전체 일별'!$B:$B,"<="&$C15) -> 223713881 | F15: =SUMIFS('전체 일별'!$L:$L,'전체 일별'!$B:$B,">="&$B15,'전체 일별'!$B:$B,"<="&$C15) -> 38417902 | G15: =SUMIFS('전체 일별'!$O:$O,'전체 일별'!$B:$B,">="&$B15,'전체 일별'!$B:$B,"<="&$C15) -> 14594 | H15: =SUMIFS('전체 일별'!$AQ:$AQ,'전체 일별'!$B:$B,">="&$B15,'전체 일별'!$B:$B,"<="&$C15) -> 9434 | I15: =SUMIFS('전체 일별'!$AR:$AR,'전체 일별'!$B:$B,">="&$B15,'전체 일별'!$B:$B,"<="&$C15) -> 6591 | J15: =SUMIFS('전체 일별'!$AJ:$AJ,'전체 일별'!$B:$B,">="&$B15,'전체 일별'!$B:$B,"<="&$C15) -> 2722 | K15: =SUMIFS('전체 일별'!$Z:$Z,'전체 일별'!$B:$B,">="&$B15,'전체 일별'!$B:$B,"<="&$C15) -> 1945 | L15: =SUMIFS('전체 일별'!$AL:$AL,'전체 일별'!$B:$B,">="&$B15,'전체 일별'!$B:$B,"<="&$C15) -> 22789 | M15: =SUMIFS('전체 일별'!$AO:$AO,'전체 일별'!$B:$B,">="&$B15,'전체 일별'!$B:$B,"<="&$C15) -> 21388 | N15: =SUMIFS('전체 일별'!$AP:$AP,'전체 일별'!$B:$B,">="&$B15,'전체 일별'!$B:$B,"<="&$C15) -> 528 | O15: =F15/J15 -> 14113.851 | P15: =IFERROR(F15/K15,0) -> 19752.135 | Q15: =I15/H15 -> 0.69864321 | R15: =J15/I15 -> 0.41298741 | S15: =K15/I15 -> 0.29509938 | T15: =IFERROR(N15/(M15+N15),0) -> 0.024091988 | U15: =IFERROR(E15/M15,0) -> 10459.785 | V15: =AVERAGEIFS('전체 일별'!$AF:$AF,'전체 일별'!$B:$B,">="&$B15,'전체 일별'!$B:$B,"<="&$C15) -> 0.10291935 | W15: =AVERAGEIFS('전체 일별'!$AB:$AB,'전체 일별'!$B:$B,">="&$B15,'전체 일별'!$B:$B,"<="&$C15) -> 0.13314516 | X15: =AVERAGEIFS('전체 일별'!$X:$X,'전체 일별'!$B:$B,">="&$B15,'전체 일별'!$B:$B,"<="&$C15) -> 0.1596 | Y15: =AVERAGEIFS('전체 일별'!$BG:$BG,'전체 일별'!$B:$B,">="&$B15,'전체 일별'!$B:$B,"<="&$C15) -> 0.2289871 | Z15: =AVERAGEIFS('전체 일별'!$BI:$BI,'전체 일별'!$B:$B,">="&$B15,'전체 일별'!$B:$B,"<="&$C15) -> 0.32639677 | AA15: =1/(AVERAGE(V11:V13)/AVERAGE($Z11:$Z13)) -> 2.9414891 | AB15: =1/(AVERAGE(W11:W13)/AVERAGE($Z11:$Z13)) -> 2.1461074 | AC15: =1/(AVERAGE(X11:X13)/AVERAGE($Z11:$Z13)) -> 1.833916 | AD15: =1/(AVERAGE(Y11:Y13)/AVERAGE($Z11:$Z13)) -> 1.3627261 | AE15: *전월 건너뛰고 최근 3개월의 평균값
B16: 45689 | C16: 45716 | D16: 25년 2월 | E16: =SUMIFS('전체 일별'!$BA:$BA,'전체 일별'!$B:$B,">="&$B16,'전체 일별'!$B:$B,"<="&$C16) -> 235359747 | F16: =SUMIFS('전체 일별'!$L:$L,'전체 일별'!$B:$B,">="&$B16,'전체 일별'!$B:$B,"<="&$C16) -> 35702733 | G16: =SUMIFS('전체 일별'!$O:$O,'전체 일별'!$B:$B,">="&$B16,'전체 일별'!$B:$B,"<="&$C16) -> 11658 | H16: =SUMIFS('전체 일별'!$AQ:$AQ,'전체 일별'!$B:$B,">="&$B16,'전체 일별'!$B:$B,"<="&$C16) -> 7539 | I16: =SUMIFS('전체 일별'!$AR:$AR,'전체 일별'!$B:$B,">="&$B16,'전체 일별'!$B:$B,"<="&$C16) -> 5761 | J16: =SUMIFS('전체 일별'!$AJ:$AJ,'전체 일별'!$B:$B,">="&$B16,'전체 일별'!$B:$B,"<="&$C16) -> 2700 | K16: =SUMIFS('전체 일별'!$Z:$Z,'전체 일별'!$B:$B,">="&$B16,'전체 일별'!$B:$B,"<="&$C16) -> 1957 | L16: =SUMIFS('전체 일별'!$AL:$AL,'전체 일별'!$B:$B,">="&$B16,'전체 일별'!$B:$B,"<="&$C16) -> 23767 | M16: =SUMIFS('전체 일별'!$AO:$AO,'전체 일별'!$B:$B,">="&$B16,'전체 일별'!$B:$B,"<="&$C16) -> 22336 | N16: =SUMIFS('전체 일별'!$AP:$AP,'전체 일별'!$B:$B,">="&$B16,'전체 일별'!$B:$B,"<="&$C16) -> 575 | O16: =F16/J16 -> 13223.234 | P16: =IFERROR(F16/K16,0) -> 18243.604 | Q16: =I16/H16 -> 0.7641597 | R16: =J16/I16 -> 0.46866863 | S16: =K16/I16 -> 0.33969797 | T16: =IFERROR(N16/(M16+N16),0) -> 0.025097115 | U16: =IFERROR(E16/M16,0) -> 10537.238 | V16: =AVERAGEIFS('전체 일별'!$AF:$AF,'전체 일별'!$B:$B,">="&$B16,'전체 일별'!$B:$B,"<="&$C16) -> 0.11013571 | W16: =AVERAGEIFS('전체 일별'!$AB:$AB,'전체 일별'!$B:$B,">="&$B16,'전체 일별'!$B:$B,"<="&$C16) -> 0.15403214 | X16: =AVERAGEIFS('전체 일별'!$X:$X,'전체 일별'!$B:$B,">="&$B16,'전체 일별'!$B:$B,"<="&$C16) -> 0.186675 | Y16: =AVERAGEIFS('전체 일별'!$BG:$BG,'전체 일별'!$B:$B,">="&$B16,'전체 일별'!$B:$B,"<="&$C16) -> 0.26208214 | Z16: =AVERAGEIFS('전체 일별'!$BI:$BI,'전체 일별'!$B:$B,">="&$B16,'전체 일별'!$B:$B,"<="&$C16) -> 0.29198929 | AA16: =1/(AVERAGE(V12:V14)/AVERAGE($Z12:$Z14)) -> 2.9229357 | AB16: =1/(AVERAGE(W12:W14)/AVERAGE($Z12:$Z14)) -> 2.1380397 | AC16: =1/(AVERAGE(X12:X14)/AVERAGE($Z12:$Z14)) -> 1.8412036 | AD16: =1/(AVERAGE(Y12:Y14)/AVERAGE($Z12:$Z14)) -> 1.3495074
B17: 45717 | C17: 45747 | D17: 25년 3월 | E17: =SUMIFS('전체 일별'!$BA:$BA,'전체 일별'!$B:$B,">="&$B17,'전체 일별'!$B:$B,"<="&$C17) -> 315567867 | F17: =SUMIFS('전체 일별'!$L:$L,'전체 일별'!$B:$B,">="&$B17,'전체 일별'!$B:$B,"<="&$C17) -> 61775162 | G17: =SUMIFS('전체 일별'!$O:$O,'전체 일별'!$B:$B,">="&$B17,'전체 일별'!$B:$B,"<="&$C17) -> 21594 | H17: =SUMIFS('전체 일별'!$AQ:$AQ,'전체 일별'!$B:$B,">="&$B17,'전체 일별'!$B:$B,"<="&$C17) -> 13637 | I17: =SUMIFS('전체 일별'!$AR:$AR,'전체 일별'!$B:$B,">="&$B17,'전체 일별'!$B:$B,"<="&$C17) -> 11583 | J17: =SUMIFS('전체 일별'!$AJ:$AJ,'전체 일별'!$B:$B,">="&$B17,'전체 일별'!$B:$B,"<="&$C17) -> 4921 | K17: =SUMIFS('전체 일별'!$Z:$Z,'전체 일별'!$B:$B,">="&$B17,'전체 일별'!$B:$B,"<="&$C17) -> 3493 | L17: =SUMIFS('전체 일별'!$AL:$AL,'전체 일별'!$B:$B,">="&$B17,'전체 일별'!$B:$B,"<="&$C17) -> 31343 | M17: =SUMIFS('전체 일별'!$AO:$AO,'전체 일별'!$B:$B,">="&$B17,'전체 일별'!$B:$B,"<="&$C17) -> 29413 | N17: =SUMIFS('전체 일별'!$AP:$AP,'전체 일별'!$B:$B,">="&$B17,'전체 일별'!$B:$B,"<="&$C17) -> 817 | O17: =F17/J17 -> 12553.376 | P17: =IFERROR(F17/K17,0) -> 17685.417 | Q17: =I17/H17 -> 0.84938036 | R17: =J17/I17 -> 0.42484676 | S17: =K17/I17 -> 0.30156263 | T17: =IFERROR(N17/(M17+N17),0) -> 0.027026133 | U17: =IFERROR(E17/M17,0) -> 10728.857 | V17: =AVERAGEIFS('전체 일별'!$AF:$AF,'전체 일별'!$B:$B,">="&$B17,'전체 일별'!$B:$B,"<="&$C17) -> 0.083790323 | W17: =AVERAGEIFS('전체 일별'!$AB:$AB,'전체 일별'!$B:$B,">="&$B17,'전체 일별'!$B:$B,"<="&$C17) -> 0.13226129 | X17: =AVERAGEIFS('전체 일별'!$X:$X,'전체 일별'!$B:$B,">="&$B17,'전체 일별'!$B:$B,"<="&$C17) -> 0.16101613 | Y17: =AVERAGEIFS('전체 일별'!$BG:$BG,'전체 일별'!$B:$B,">="&$B17,'전체 일별'!$B:$B,"<="&$C17) -> 0.25195806 | Z17: =AVERAGEIFS('전체 일별'!$BI:$BI,'전체 일별'!$B:$B,">="&$B17,'전체 일별'!$B:$B,"<="&$C17) -> 0.37339032 | AA17: =1/(AVERAGE(V13:V15)/AVERAGE($Z13:$Z15)) -> 2.9698314 | AB17: =1/(AVERAGE(W13:W15)/AVERAGE($Z13:$Z15)) -> 2.2417854 | AC17: =1/(AVERAGE(X13:X15)/AVERAGE($Z13:$Z15)) -> 1.9099018 | AD17: =1/(AVERAGE(Y13:Y15)/AVERAGE($Z13:$Z15)) -> 1.3807579
B18: 45748 | C18: 45777 | D18: 25년 4월 | E18: =SUMIFS('전체 일별'!$BA:$BA,'전체 일별'!$B:$B,">="&$B18,'전체 일별'!$B:$B,"<="&$C18) -> 379106261 | F18: =SUMIFS('전체 일별'!$L:$L,'전체 일별'!$B:$B,">="&$B18,'전체 일별'!$B:$B,"<="&$C18) -> 69261943 | G18: =SUMIFS('전체 일별'!$O:$O,'전체 일별'!$B:$B,">="&$B18,'전체 일별'!$B:$B,"<="&$C18) -> 17815 | H18: =SUMIFS('전체 일별'!$AQ:$AQ,'전체 일별'!$B:$B,">="&$B18,'전체 일별'!$B:$B,"<="&$C18) -> 13202 | I18: =SUMIFS('전체 일별'!$AR:$AR,'전체 일별'!$B:$B,">="&$B18,'전체 일별'!$B:$B,"<="&$C18) -> 11586 | J18: =SUMIFS('전체 일별'!$AJ:$AJ,'전체 일별'!$B:$B,">="&$B18,'전체 일별'!$B:$B,"<="&$C18) -> 5800 | K18: =SUMIFS('전체 일별'!$Z:$Z,'전체 일별'!$B:$B,">="&$B18,'전체 일별'!$B:$B,"<="&$C18) -> 4017 | L18: =SUMIFS('전체 일별'!$AL:$AL,'전체 일별'!$B:$B,">="&$B18,'전체 일별'!$B:$B,"<="&$C18) -> 37674 | M18: =SUMIFS('전체 일별'!$AO:$AO,'전체 일별'!$B:$B,">="&$B18,'전체 일별'!$B:$B,"<="&$C18) -> 35184 | N18: =SUMIFS('전체 일별'!$AP:$AP,'전체 일별'!$B:$B,">="&$B18,'전체 일별'!$B:$B,"<="&$C18) -> 896 | O18: =F18/J18 -> 11941.714 | P18: =IFERROR(F18/K18,0) -> 17242.206 | Q18: =I18/H18 -> 0.8775943 | R18: =J18/I18 -> 0.50060418 | S18: =K18/I18 -> 0.34671155 | T18: =IFERROR(N18/(M18+N18),0) -> 0.024833703 | U18: =IFERROR(E18/M18,0) -> 10774.962 | V18: =AVERAGEIFS('전체 일별'!$AF:$AF,'전체 일별'!$B:$B,">="&$B18,'전체 일별'!$B:$B,"<="&$C18) -> 0.10652333 | W18: =AVERAGEIFS('전체 일별'!$AB:$AB,'전체 일별'!$B:$B,">="&$B18,'전체 일별'!$B:$B,"<="&$C18) -> 0.16188 | X18: =AVERAGEIFS('전체 일별'!$X:$X,'전체 일별'!$B:$B,">="&$B18,'전체 일별'!$B:$B,"<="&$C18) -> 0.1928 | Y18: =AVERAGEIFS('전체 일별'!$BG:$BG,'전체 일별'!$B:$B,">="&$B18,'전체 일별'!$B:$B,"<="&$C18) -> 0.28508 | Z18: =AVERAGEIFS('전체 일별'!$BI:$BI,'전체 일별'!$B:$B,">="&$B18,'전체 일별'!$B:$B,"<="&$C18) -> 0.40518667 | AA18: =1/(AVERAGE(V14:V16)/AVERAGE($Z14:$Z16)) -> 2.8673502 | AB18: =1/(AVERAGE(W14:W16)/AVERAGE($Z14:$Z16)) -> 2.1310083 | AC18: =1/(AVERAGE(X14:X16)/AVERAGE($Z14:$Z16)) -> 1.7989578 | AD18: =1/(AVERAGE(Y14:Y16)/AVERAGE($Z14:$Z16)) -> 1.2802199
B19: 45778 | C19: 45808 | D19: 25년 5월 | E19: =SUMIFS('전체 일별'!$BA:$BA,'전체 일별'!$B:$B,">="&$B19,'전체 일별'!$B:$B,"<="&$C19) -> 447113043 | F19: =SUMIFS('전체 일별'!$L:$L,'전체 일별'!$B:$B,">="&$B19,'전체 일별'!$B:$B,"<="&$C19) -> 78454723 | G19: =SUMIFS('전체 일별'!$O:$O,'전체 일별'!$B:$B,">="&$B19,'전체 일별'!$B:$B,"<="&$C19) -> 19561 | H19: =SUMIFS('전체 일별'!$AQ:$AQ,'전체 일별'!$B:$B,">="&$B19,'전체 일별'!$B:$B,"<="&$C19) -> 14822 | I19: =SUMIFS('전체 일별'!$AR:$AR,'전체 일별'!$B:$B,">="&$B19,'전체 일별'!$B:$B,"<="&$C19) -> 13368 | J19: =SUMIFS('전체 일별'!$AJ:$AJ,'전체 일별'!$B:$B,">="&$B19,'전체 일별'!$B:$B,"<="&$C19) -> 6293 | K19: =SUMIFS('전체 일별'!$Z:$Z,'전체 일별'!$B:$B,">="&$B19,'전체 일별'!$B:$B,"<="&$C19) -> 4616 | L19: =SUMIFS('전체 일별'!$AL:$AL,'전체 일별'!$B:$B,">="&$B19,'전체 일별'!$B:$B,"<="&$C19) -> 45516 | M19: =SUMIFS('전체 일별'!$AO:$AO,'전체 일별'!$B:$B,">="&$B19,'전체 일별'!$B:$B,"<="&$C19) -> 42042 | N19: =SUMIFS('전체 일별'!$AP:$AP,'전체 일별'!$B:$B,">="&$B19,'전체 일별'!$B:$B,"<="&$C19) -> 1237 | O19: =F19/J19 -> 12466.983 | P19: =IFERROR(F19/K19,0) -> 16996.257 | Q19: =I19/H19 -> 0.90190258 | R19: =J19/I19 -> 0.47075105 | S19: =K19/I19 -> 0.34530221 | T19: =IFERROR(N19/(M19+N19),0) -> 0.028581991 | U19: =IFERROR(E19/M19,0) -> 10634.914 | V19: =AVERAGEIFS('전체 일별'!$AF:$AF,'전체 일별'!$B:$B,">="&$B19,'전체 일별'!$B:$B,"<="&$C19) -> 0.090970968 | W19: =AVERAGEIFS('전체 일별'!$AB:$AB,'전체 일별'!$B:$B,">="&$B19,'전체 일별'!$B:$B,"<="&$C19) -> 0.14526129 | X19: =AVERAGEIFS('전체 일별'!$X:$X,'전체 일별'!$B:$B,">="&$B19,'전체 일별'!$B:$B,"<="&$C19) -> 0.17693226 | Y19: =AVERAGEIFS('전체 일별'!$BG:$BG,'전체 일별'!$B:$B,">="&$B19,'전체 일별'!$B:$B,"<="&$C19) -> 0.26690645 | Z19: =AVERAGEIFS('전체 일별'!$BI:$BI,'전체 일별'!$B:$B,">="&$B19,'전체 일별'!$B:$B,"<="&$C19) -> 0.38894516 | AA19: =1/(AVERAGE(V15:V17)/AVERAGE($Z15:$Z17)) -> 3.3410537 | AB19: =1/(AVERAGE(W15:W17)/AVERAGE($Z15:$Z17)) -> 2.364533 | AC19: =1/(AVERAGE(X15:X17)/AVERAGE($Z15:$Z17)) -> 1.9550438 | AD19: =1/(AVERAGE(Y15:Y17)/AVERAGE($Z15:$Z17)) -> 1.3347778
B20: 45809 | C20: 45838 | D20: 25년 6월 | E20: =SUMIFS('전체 일별'!$BA:$BA,'전체 일별'!$B:$B,">="&$B20,'전체 일별'!$B:$B,"<="&$C20) -> 553181294 | F20: =SUMIFS('전체 일별'!$L:$L,'전체 일별'!$B:$B,">="&$B20,'전체 일별'!$B:$B,"<="&$C20) -> 100123746 | G20: =SUMIFS('전체 일별'!$O:$O,'전체 일별'!$B:$B,">="&$B20,'전체 일별'!$B:$B,"<="&$C20) -> 25741 | H20: =SUMIFS('전체 일별'!$AQ:$AQ,'전체 일별'!$B:$B,">="&$B20,'전체 일별'!$B:$B,"<="&$C20) -> 19124 | I20: =SUMIFS('전체 일별'!$AR:$AR,'전체 일별'!$B:$B,">="&$B20,'전체 일별'!$B:$B,"<="&$C20) -> 16670 | J20: =SUMIFS('전체 일별'!$AJ:$AJ,'전체 일별'!$B:$B,">="&$B20,'전체 일별'!$B:$B,"<="&$C20) -> 7587 | K20: =SUMIFS('전체 일별'!$Z:$Z,'전체 일별'!$B:$B,">="&$B20,'전체 일별'!$B:$B,"<="&$C20) -> 5742 | L20: =SUMIFS('전체 일별'!$AL:$AL,'전체 일별'!$B:$B,">="&$B20,'전체 일별'!$B:$B,"<="&$C20) -> 64568 | M20: =SUMIFS('전체 일별'!$AO:$AO,'전체 일별'!$B:$B,">="&$B20,'전체 일별'!$B:$B,"<="&$C20) -> 51211 | N20: =SUMIFS('전체 일별'!$AP:$AP,'전체 일별'!$B:$B,">="&$B20,'전체 일별'!$B:$B,"<="&$C20) -> 1531 | O20: =F20/J20 -> 13196.75 | P20: =IFERROR(F20/K20,0) -> 17437.086 | Q20: =I20/H20 -> 0.87167956 | R20: =J20/I20 -> 0.45512897 | S20: =K20/I20 -> 0.34445111 | T20: =IFERROR(N20/(M20+N20),0) -> 0.029028099 | U20: =IFERROR(E20/M20,0) -> 10802.001 | V20: =AVERAGEIFS('전체 일별'!$AF:$AF,'전체 일별'!$B:$B,">="&$B20,'전체 일별'!$B:$B,"<="&$C20) -> 0.09001 | W20: =AVERAGEIFS('전체 일별'!$AB:$AB,'전체 일별'!$B:$B,">="&$B20,'전체 일별'!$B:$B,"<="&$C20) -> 0.14293333 | X20: =AVERAGEIFS('전체 일별'!$X:$X,'전체 일별'!$B:$B,">="&$B20,'전체 일별'!$B:$B,"<="&$C20) -> 0.17341667 | Y20: =AVERAGEIFS('전체 일별'!$BG:$BG,'전체 일별'!$B:$B,">="&$B20,'전체 일별'!$B:$B,"<="&$C20) -> 0.26677 | Z20: =AVERAGEIFS('전체 일별'!$BI:$BI,'전체 일별'!$B:$B,">="&$B20,'전체 일별'!$B:$B,"<="&$C20) -> 0.38584 | AA20: =1/(AVERAGE(V16:V18)/AVERAGE($Z16:$Z18)) -> 3.5632169 | AB20: =1/(AVERAGE(W16:W18)/AVERAGE($Z16:$Z18)) -> 2.3887321 | AC20: =1/(AVERAGE(X16:X18)/AVERAGE($Z16:$Z18)) -> 1.9807287 | AD20: =1/(AVERAGE(Y16:Y18)/AVERAGE($Z16:$Z18)) -> 1.3396811
B21: 45839 | C21: 45869 | D21: 25년 7월 | E21: =SUMIFS('전체 일별'!$BA:$BA,'전체 일별'!$B:$B,">="&$B21,'전체 일별'!$B:$B,"<="&$C21) -> 697002826 | F21: =SUMIFS('전체 일별'!$L:$L,'전체 일별'!$B:$B,">="&$B21,'전체 일별'!$B:$B,"<="&$C21) -> 167116366 | G21: =SUMIFS('전체 일별'!$O:$O,'전체 일별'!$B:$B,">="&$B21,'전체 일별'!$B:$B,"<="&$C21) -> 35054 | H21: =SUMIFS('전체 일별'!$AQ:$AQ,'전체 일별'!$B:$B,">="&$B21,'전체 일별'!$B:$B,"<="&$C21) -> 25695 | I21: =SUMIFS('전체 일별'!$AR:$AR,'전체 일별'!$B:$B,">="&$B21,'전체 일별'!$B:$B,"<="&$C21) -> 22582 | J21: =SUMIFS('전체 일별'!$AJ:$AJ,'전체 일별'!$B:$B,">="&$B21,'전체 일별'!$B:$B,"<="&$C21) -> 10300 | K21: =SUMIFS('전체 일별'!$Z:$Z,'전체 일별'!$B:$B,">="&$B21,'전체 일별'!$B:$B,"<="&$C21) -> 8122 | L21: =SUMIFS('전체 일별'!$AL:$AL,'전체 일별'!$B:$B,">="&$B21,'전체 일별'!$B:$B,"<="&$C21) -> 81394 | M21: =SUMIFS('전체 일별'!$AO:$AO,'전체 일별'!$B:$B,">="&$B21,'전체 일별'!$B:$B,"<="&$C21) -> 63467 | N21: =SUMIFS('전체 일별'!$AP:$AP,'전체 일별'!$B:$B,">="&$B21,'전체 일별'!$B:$B,"<="&$C21) -> 1837 | O21: =F21/J21 -> 16224.89 | P21: =IFERROR(F21/K21,0) -> 20575.765 | Q21: =I21/H21 -> 0.87884802 | R21: =J21/I21 -> 0.45611549 | S21: =K21/I21 -> 0.35966699 | T21: =IFERROR(N21/(M21+N21),0) -> 0.028129977 | U21: =IFERROR(E21/M21,0) -> 10982.13 | V21: =AVERAGEIFS('전체 일별'!$AF:$AF,'전체 일별'!$B:$B,">="&$B21,'전체 일별'!$B:$B,"<="&$C21) -> 0.091151613 | W21: =AVERAGEIFS('전체 일별'!$AB:$AB,'전체 일별'!$B:$B,">="&$B21,'전체 일별'!$B:$B,"<="&$C21) -> 0.1457129 | X21: =AVERAGEIFS('전체 일별'!$X:$X,'전체 일별'!$B:$B,">="&$B21,'전체 일별'!$B:$B,"<="&$C21) -> 0.17883871 | Y21: =AVERAGEIFS('전체 일별'!$BG:$BG,'전체 일별'!$B:$B,">="&$B21,'전체 일별'!$B:$B,"<="&$C21) -> 0.26662581 | Z21: =AVERAGEIFS('전체 일별'!$BI:$BI,'전체 일별'!$B:$B,">="&$B21,'전체 일별'!$B:$B,"<="&$C21) -> 0.37973226 | AA21: =1/(AVERAGE(V17:V19)/AVERAGE($Z17:$Z19)) -> 4.1506789 | AB21: =1/(AVERAGE(W17:W19)/AVERAGE($Z17:$Z19)) -> 2.6570671 | AC21: =1/(AVERAGE(X17:X19)/AVERAGE($Z17:$Z19)) -> 2.1997658 | AD21: =1/(AVERAGE(Y17:Y19)/AVERAGE($Z17:$Z19)) -> 1.4522422
B22: 45870 | C22: 45900 | D22: 25년 8월 | E22: =SUMIFS('전체 일별'!$BA:$BA,'전체 일별'!$B:$B,">="&$B22,'전체 일별'!$B:$B,"<="&$C22) -> 753028059 | F22: =SUMIFS('전체 일별'!$L:$L,'전체 일별'!$B:$B,">="&$B22,'전체 일별'!$B:$B,"<="&$C22) -> 130112974 | G22: =SUMIFS('전체 일별'!$O:$O,'전체 일별'!$B:$B,">="&$B22,'전체 일별'!$B:$B,"<="&$C22) -> 41421 | H22: =SUMIFS('전체 일별'!$AQ:$AQ,'전체 일별'!$B:$B,">="&$B22,'전체 일별'!$B:$B,"<="&$C22) -> 26194 | I22: =SUMIFS('전체 일별'!$AR:$AR,'전체 일별'!$B:$B,">="&$B22,'전체 일별'!$B:$B,"<="&$C22) -> 22532 | J22: =SUMIFS('전체 일별'!$AJ:$AJ,'전체 일별'!$B:$B,">="&$B22,'전체 일별'!$B:$B,"<="&$C22) -> 9549 | K22: =SUMIFS('전체 일별'!$Z:$Z,'전체 일별'!$B:$B,">="&$B22,'전체 일별'!$B:$B,"<="&$C22) -> 7003 | L22: =SUMIFS('전체 일별'!$AL:$AL,'전체 일별'!$B:$B,">="&$B22,'전체 일별'!$B:$B,"<="&$C22) -> 88419 | M22: =SUMIFS('전체 일별'!$AO:$AO,'전체 일별'!$B:$B,">="&$B22,'전체 일별'!$B:$B,"<="&$C22) -> 71334 | N22: =SUMIFS('전체 일별'!$AP:$AP,'전체 일별'!$B:$B,">="&$B22,'전체 일별'!$B:$B,"<="&$C22) -> 2113 | O22: =F22/J22 -> 13625.822 | P22: =IFERROR(F22/K22,0) -> 18579.605 | Q22: =I22/H22 -> 0.86019699 | R22: =J22/I22 -> 0.42379727 | S22: =K22/I22 -> 0.31080241 | T22: =IFERROR(N22/(M22+N22),0) -> 0.028769044 | U22: =IFERROR(E22/M22,0) -> 10556.369 | V22: =AVERAGEIFS('전체 일별'!$AF:$AF,'전체 일별'!$B:$B,">="&$B22,'전체 일별'!$B:$B,"<="&$C22) -> 0.078390323 | W22: =AVERAGEIFS('전체 일별'!$AB:$AB,'전체 일별'!$B:$B,">="&$B22,'전체 일별'!$B:$B,"<="&$C22) -> 0.12290645 | X22: =AVERAGEIFS('전체 일별'!$X:$X,'전체 일별'!$B:$B,">="&$B22,'전체 일별'!$B:$B,"<="&$C22) -> 0.15313871 | Y22: =AVERAGEIFS('전체 일별'!$BG:$BG,'전체 일별'!$B:$B,">="&$B22,'전체 일별'!$B:$B,"<="&$C22) -> 0.22661613 | Z22: =AVERAGEIFS('전체 일별'!$BI:$BI,'전체 일별'!$B:$B,">="&$B22,'전체 일별'!$B:$B,"<="&$C22) -> 0.33176452 | AA22: =1/(AVERAGE(V18:V20)/AVERAGE($Z18:$Z20)) -> 4.1041884 | AB22: =1/(AVERAGE(W18:W20)/AVERAGE($Z18:$Z20)) -> 2.6217249 | AC22: =1/(AVERAGE(X18:X20)/AVERAGE($Z18:$Z20)) -> 2.1724646 | AD22: =1/(AVERAGE(Y18:Y20)/AVERAGE($Z18:$Z20)) -> 1.4411756
B23: 45901 | C23: 45930 | D23: 25년 9월 | E23: =SUMIFS('전체 일별'!$BA:$BA,'전체 일별'!$B:$B,">="&$B23,'전체 일별'!$B:$B,"<="&$C23) -> 773570302 | F23: =SUMIFS('전체 일별'!$L:$L,'전체 일별'!$B:$B,">="&$B23,'전체 일별'!$B:$B,"<="&$C23) -> 124710628 | G23: =SUMIFS('전체 일별'!$O:$O,'전체 일별'!$B:$B,">="&$B23,'전체 일별'!$B:$B,"<="&$C23) -> 36364 | H23: =SUMIFS('전체 일별'!$AQ:$AQ,'전체 일별'!$B:$B,">="&$B23,'전체 일별'!$B:$B,"<="&$C23) -> 23084 | I23: =SUMIFS('전체 일별'!$AR:$AR,'전체 일별'!$B:$B,">="&$B23,'전체 일별'!$B:$B,"<="&$C23) -> 19551 | J23: =SUMIFS('전체 일별'!$AJ:$AJ,'전체 일별'!$B:$B,">="&$B23,'전체 일별'!$B:$B,"<="&$C23) -> 8660 | K23: =SUMIFS('전체 일별'!$Z:$Z,'전체 일별'!$B:$B,">="&$B23,'전체 일별'!$B:$B,"<="&$C23) -> 6449 | L23: =SUMIFS('전체 일별'!$AL:$AL,'전체 일별'!$B:$B,">="&$B23,'전체 일별'!$B:$B,"<="&$C23) -> 86986 | M23: =SUMIFS('전체 일별'!$AO:$AO,'전체 일별'!$B:$B,">="&$B23,'전체 일별'!$B:$B,"<="&$C23) -> 71355 | N23: =SUMIFS('전체 일별'!$AP:$AP,'전체 일별'!$B:$B,">="&$B23,'전체 일별'!$B:$B,"<="&$C23) -> 2186 | O23: =F23/J23 -> 14400.765 | P23: =IFERROR(F23/K23,0) -> 19337.979 | Q23: =I23/H23 -> 0.84695027 | R23: =J23/I23 -> 0.44294409 | S23: =K23/I23 -> 0.32985525 | T23: =IFERROR(N23/(M23+N23),0) -> 0.029724915 | U23: =IFERROR(E23/M23,0) -> 10841.151 | V23: =AVERAGEIFS('전체 일별'!$AF:$AF,'전체 일별'!$B:$B,">="&$B23,'전체 일별'!$B:$B,"<="&$C23) -> 0.08269 | W23: =AVERAGEIFS('전체 일별'!$AB:$AB,'전체 일별'!$B:$B,">="&$B23,'전체 일별'!$B:$B,"<="&$C23) -> 0.12488 | X23: =AVERAGEIFS('전체 일별'!$X:$X,'전체 일별'!$B:$B,">="&$B23,'전체 일별'!$B:$B,"<="&$C23) -> 0.15226667 | Y23: =AVERAGEIFS('전체 일별'!$BG:$BG,'전체 일별'!$B:$B,">="&$B23,'전체 일별'!$B:$B,"<="&$C23) -> 0.22862667 | Z23: =AVERAGEIFS('전체 일별'!$BI:$BI,'전체 일별'!$B:$B,">="&$B23,'전체 일별'!$B:$B,"<="&$C23) -> 0.33773667 | AA23: =1/(AVERAGE(V19:V21)/AVERAGE($Z19:$Z21)) -> 4.2424814 | AB23: =1/(AVERAGE(W19:W21)/AVERAGE($Z19:$Z21)) -> 2.6607453 | AC23: =1/(AVERAGE(X19:X21)/AVERAGE($Z19:$Z21)) -> 2.1816788 | AD23: =1/(AVERAGE(Y19:Y21)/AVERAGE($Z19:$Z21)) -> 1.4426017
B24: 45931 | C24: 45961 | D24: 25년 10월 | E24: =SUMIFS('전체 일별'!$BA:$BA,'전체 일별'!$B:$B,">="&$B24,'전체 일별'!$B:$B,"<="&$C24) -> 900133114 | F24: =SUMIFS('전체 일별'!$L:$L,'전체 일별'!$B:$B,">="&$B24,'전체 일별'!$B:$B,"<="&$C24) -> 199016283 | G24: =SUMIFS('전체 일별'!$O:$O,'전체 일별'!$B:$B,">="&$B24,'전체 일별'!$B:$B,"<="&$C24) -> 43324 | H24: =SUMIFS('전체 일별'!$AQ:$AQ,'전체 일별'!$B:$B,">="&$B24,'전체 일별'!$B:$B,"<="&$C24) -> 28501 | I24: =SUMIFS('전체 일별'!$AR:$AR,'전체 일별'!$B:$B,">="&$B24,'전체 일별'!$B:$B,"<="&$C24) -> 24449 | J24: =SUMIFS('전체 일별'!$AJ:$AJ,'전체 일별'!$B:$B,">="&$B24,'전체 일별'!$B:$B,"<="&$C24) -> 10220 | K24: =SUMIFS('전체 일별'!$Z:$Z,'전체 일별'!$B:$B,">="&$B24,'전체 일별'!$B:$B,"<="&$C24) -> 7754 | L24: =SUMIFS('전체 일별'!$AL:$AL,'전체 일별'!$B:$B,">="&$B24,'전체 일별'!$B:$B,"<="&$C24) -> 99409 | M24: =SUMIFS('전체 일별'!$AO:$AO,'전체 일별'!$B:$B,">="&$B24,'전체 일별'!$B:$B,"<="&$C24) -> 79394 | N24: =SUMIFS('전체 일별'!$AP:$AP,'전체 일별'!$B:$B,">="&$B24,'전체 일별'!$B:$B,"<="&$C24) -> 2277 | O24: =F24/J24 -> 19473.218 | P24: =IFERROR(F24/K24,0) -> 25666.273 | Q24: =I24/H24 -> 0.85782955 | R24: =J24/I24 -> 0.41801301 | S24: =K24/I24 -> 0.31714999 | T24: =IFERROR(N24/(M24+N24),0) -> 0.027880153 | U24: =IFERROR(E24/M24,0) -> 11337.546 | V24: =AVERAGEIFS('전체 일별'!$AF:$AF,'전체 일별'!$B:$B,">="&$B24,'전체 일별'!$B:$B,"<="&$C24) -> 0.080093548 | W24: =AVERAGEIFS('전체 일별'!$AB:$AB,'전체 일별'!$B:$B,">="&$B24,'전체 일별'!$B:$B,"<="&$C24) -> 0.11995484 | X24: =AVERAGEIFS('전체 일별'!$X:$X,'전체 일별'!$B:$B,">="&$B24,'전체 일별'!$B:$B,"<="&$C24) -> 0.14634839 | Y24: =AVERAGEIFS('전체 일별'!$BG:$BG,'전체 일별'!$B:$B,">="&$B24,'전체 일별'!$B:$B,"<="&$C24) -> 0.22246774 | Z24: =AVERAGEIFS('전체 일별'!$BI:$BI,'전체 일별'!$B:$B,">="&$B24,'전체 일별'!$B:$B,"<="&$C24) -> 0.32783871 | AA24: =1/(AVERAGE(V20:V22)/AVERAGE($Z20:$Z22)) -> 4.2278119 | AB24: =1/(AVERAGE(W20:W22)/AVERAGE($Z20:$Z22)) -> 2.6663336 | AC24: =1/(AVERAGE(X20:X22)/AVERAGE($Z20:$Z22)) -> 2.1712497 | AD24: =1/(AVERAGE(Y20:Y22)/AVERAGE($Z20:$Z22)) -> 1.4438415
B25: 45962 | C25: 45991 | D25: 25년 11월 | E25: =SUMIFS('전체 일별'!$BA:$BA,'전체 일별'!$B:$B,">="&$B25,'전체 일별'!$B:$B,"<="&$C25) -> 897464373 | F25: =SUMIFS('전체 일별'!$L:$L,'전체 일별'!$B:$B,">="&$B25,'전체 일별'!$B:$B,"<="&$C25) -> 183333176 | G25: =SUMIFS('전체 일별'!$O:$O,'전체 일별'!$B:$B,">="&$B25,'전체 일별'!$B:$B,"<="&$C25) -> 29265 | H25: =SUMIFS('전체 일별'!$AQ:$AQ,'전체 일별'!$B:$B,">="&$B25,'전체 일별'!$B:$B,"<="&$C25) -> 21116 | I25: =SUMIFS('전체 일별'!$AR:$AR,'전체 일별'!$B:$B,">="&$B25,'전체 일별'!$B:$B,"<="&$C25) -> 18618 | J25: =SUMIFS('전체 일별'!$AJ:$AJ,'전체 일별'!$B:$B,">="&$B25,'전체 일별'!$B:$B,"<="&$C25) -> 8912 | K25: =SUMIFS('전체 일별'!$Z:$Z,'전체 일별'!$B:$B,">="&$B25,'전체 일별'!$B:$B,"<="&$C25) -> 6472 | L25: =SUMIFS('전체 일별'!$AL:$AL,'전체 일별'!$B:$B,">="&$B25,'전체 일별'!$B:$B,"<="&$C25) -> 96658 | M25: =SUMIFS('전체 일별'!$AO:$AO,'전체 일별'!$B:$B,">="&$B25,'전체 일별'!$B:$B,"<="&$C25) -> 86602 | N25: =SUMIFS('전체 일별'!$AP:$AP,'전체 일별'!$B:$B,">="&$B25,'전체 일별'!$B:$B,"<="&$C25) -> 2130 | O25: =F25/J25 -> 20571.496 | P25: =IFERROR(F25/K25,0) -> 28327.129 | Q25: =I25/H25 -> 0.88170108 | R25: =J25/I25 -> 0.47867655 | S25: =K25/I25 -> 0.34762058 | T25: =IFERROR(N25/(M25+N25),0) -> 0.024004869 | U25: =IFERROR(E25/M25,0) -> 10363.091 | V25: =AVERAGEIFS('전체 일별'!$AF:$AF,'전체 일별'!$B:$B,">="&$B25,'전체 일별'!$B:$B,"<="&$C25) -> 0.091843333 | W25: =AVERAGEIFS('전체 일별'!$AB:$AB,'전체 일별'!$B:$B,">="&$B25,'전체 일별'!$B:$B,"<="&$C25) -> 0.13614333 | X25: =AVERAGEIFS('전체 일별'!$X:$X,'전체 일별'!$B:$B,">="&$B25,'전체 일별'!$B:$B,"<="&$C25) -> 0.16315667 | Y25: =AVERAGEIFS('전체 일별'!$BG:$BG,'전체 일별'!$B:$B,">="&$B25,'전체 일별'!$B:$B,"<="&$C25) -> 0.24122667 | Z25: =AVERAGEIFS('전체 일별'!$BI:$BI,'전체 일별'!$B:$B,">="&$B25,'전체 일별'!$B:$B,"<="&$C25) -> 0.35342333 | AA25: =1/(AVERAGE(V21:V23)/AVERAGE($Z21:$Z23)) -> 4.1597962 | AB25: =1/(AVERAGE(W21:W23)/AVERAGE($Z21:$Z23)) -> 2.6664172 | AC25: =1/(AVERAGE(X21:X23)/AVERAGE($Z21:$Z23)) -> 2.166745 | AD25: =1/(AVERAGE(Y21:Y23)/AVERAGE($Z21:$Z23)) -> 1.4534964
B26: 45992 | C26: 46022 | D26: 25년 12월 | E26: =SUMIFS('전체 일별'!$BA:$BA,'전체 일별'!$B:$B,">="&$B26,'전체 일별'!$B:$B,"<="&$C26) -> 1030658963 | F26: =SUMIFS('전체 일별'!$L:$L,'전체 일별'!$B:$B,">="&$B26,'전체 일별'!$B:$B,"<="&$C26) -> 286129320 | G26: =SUMIFS('전체 일별'!$O:$O,'전체 일별'!$B:$B,">="&$B26,'전체 일별'!$B:$B,"<="&$C26) -> 38275 | H26: =SUMIFS('전체 일별'!$AQ:$AQ,'전체 일별'!$B:$B,">="&$B26,'전체 일별'!$B:$B,"<="&$C26) -> 27154 | I26: =SUMIFS('전체 일별'!$AR:$AR,'전체 일별'!$B:$B,">="&$B26,'전체 일별'!$B:$B,"<="&$C26) -> 24481 | J26: =SUMIFS('전체 일별'!$AJ:$AJ,'전체 일별'!$B:$B,">="&$B26,'전체 일별'!$B:$B,"<="&$C26) -> 12663 | K26: =SUMIFS('전체 일별'!$Z:$Z,'전체 일별'!$B:$B,">="&$B26,'전체 일별'!$B:$B,"<="&$C26) -> 10784 | L26: =SUMIFS('전체 일별'!$AL:$AL,'전체 일별'!$B:$B,">="&$B26,'전체 일별'!$B:$B,"<="&$C26) -> 114524 | M26: =SUMIFS('전체 일별'!$AO:$AO,'전체 일별'!$B:$B,">="&$B26,'전체 일별'!$B:$B,"<="&$C26) -> 108288 | N26: =SUMIFS('전체 일별'!$AP:$AP,'전체 일별'!$B:$B,">="&$B26,'전체 일별'!$B:$B,"<="&$C26) -> 2013 | O26: =F26/J26 -> 22595.698 | P26: =IFERROR(F26/K26,0) -> 26532.763 | Q26: =I26/H26 -> 0.90156146 | R26: =J26/I26 -> 0.51725828 | S26: =K26/I26 -> 0.44050488 | T26: =IFERROR(N26/(M26+N26),0) -> 0.018250061 | U26: =IFERROR(E26/M26,0) -> 9517.7579 | V26: =AVERAGEIFS('전체 일별'!$AF:$AF,'전체 일별'!$B:$B,">="&$B26,'전체 일별'!$B:$B,"<="&$C26) -> 0.1043 | W26: =AVERAGEIFS('전체 일별'!$AB:$AB,'전체 일별'!$B:$B,">="&$B26,'전체 일별'!$B:$B,"<="&$C26) -> 0.16181935 | X26: =AVERAGEIFS('전체 일별'!$X:$X,'전체 일별'!$B:$B,">="&$B26,'전체 일별'!$B:$B,"<="&$C26) -> 0.19909032 | Y26: =AVERAGEIFS('전체 일별'!$BG:$BG,'전체 일별'!$B:$B,">="&$B26,'전체 일별'!$B:$B,"<="&$C26) -> 0.2978129 | Z26: =AVERAGEIFS('전체 일별'!$BI:$BI,'전체 일별'!$B:$B,">="&$B26,'전체 일별'!$B:$B,"<="&$C26) -> 0.42697419 | AA26: =1/(AVERAGE(V22:V24)/AVERAGE($Z22:$Z24)) -> 4.1353563 | AB26: =1/(AVERAGE(W22:W24)/AVERAGE($Z22:$Z24)) -> 2.7120694 | AC26: =1/(AVERAGE(X22:X24)/AVERAGE($Z22:$Z24)) -> 2.2077069 | AD26: =1/(AVERAGE(Y22:Y24)/AVERAGE($Z22:$Z24)) -> 1.4716311
B27: 46023 | C27: 46053 | D27: 26년 1월 | E27: =SUMIFS('전체 일별'!$BA:$BA,'전체 일별'!$B:$B,">="&$B27,'전체 일별'!$B:$B,"<="&$C27) -> 1157562342 | F27: =SUMIFS('전체 일별'!$L:$L,'전체 일별'!$B:$B,">="&$B27,'전체 일별'!$B:$B,"<="&$C27) -> 271983456 | G27: =SUMIFS('전체 일별'!$O:$O,'전체 일별'!$B:$B,">="&$B27,'전체 일별'!$B:$B,"<="&$C27) -> 47724 | H27: =SUMIFS('전체 일별'!$AQ:$AQ,'전체 일별'!$B:$B,">="&$B27,'전체 일별'!$B:$B,"<="&$C27) -> 28061 | I27: =SUMIFS('전체 일별'!$AR:$AR,'전체 일별'!$B:$B,">="&$B27,'전체 일별'!$B:$B,"<="&$C27) -> 25115 | J27: =SUMIFS('전체 일별'!$AJ:$AJ,'전체 일별'!$B:$B,">="&$B27,'전체 일별'!$B:$B,"<="&$C27) -> 12182 | K27: =SUMIFS('전체 일별'!$Z:$Z,'전체 일별'!$B:$B,">="&$B27,'전체 일별'!$B:$B,"<="&$C27) -> 9262 | L27: =SUMIFS('전체 일별'!$AL:$AL,'전체 일별'!$B:$B,">="&$B27,'전체 일별'!$B:$B,"<="&$C27) -> 120633 | M27: =SUMIFS('전체 일별'!$AO:$AO,'전체 일별'!$B:$B,">="&$B27,'전체 일별'!$B:$B,"<="&$C27) -> 115246 | N27: =SUMIFS('전체 일별'!$AP:$AP,'전체 일별'!$B:$B,">="&$B27,'전체 일별'!$B:$B,"<="&$C27) -> 2084 | O27: =F27/J27 -> 22326.667 | P27: =IFERROR(F27/K27,0) -> 29365.521 | Q27: =I27/H27 -> 0.89501443 | R27: =J27/I27 -> 0.48504878 | S27: =K27/I27 -> 0.3687836 | T27: =IFERROR(N27/(M27+N27),0) -> 0.017761868 | U27: =IFERROR(E27/M27,0) -> 10044.273 | V27: =AVERAGEIFS('전체 일별'!$AF:$AF,'전체 일별'!$B:$B,">="&$B27,'전체 일별'!$B:$B,"<="&$C27) -> 0.0881 | W27: =AVERAGEIFS('전체 일별'!$AB:$AB,'전체 일별'!$B:$B,">="&$B27,'전체 일별'!$B:$B,"<="&$C27) -> 0.13939355 | X27: =AVERAGEIFS('전체 일별'!$X:$X,'전체 일별'!$B:$B,">="&$B27,'전체 일별'!$B:$B,"<="&$C27) -> 0.16923226 | Y27: =AVERAGEIFS('전체 일별'!$BG:$BG,'전체 일별'!$B:$B,">="&$B27,'전체 일별'!$B:$B,"<="&$C27) -> 0.25216774 | Z27: =AVERAGEIFS('전체 일별'!$BI:$BI,'전체 일별'!$B:$B,">="&$B27,'전체 일별'!$B:$B,"<="&$C27) -> 0.37063871 | AA27: =1/(AVERAGE(V23:V25)/AVERAGE($Z23:$Z25)) -> 4.001929 | AB27: =1/(AVERAGE(W23:W25)/AVERAGE($Z23:$Z25)) -> 2.6746905 | AC27: =1/(AVERAGE(X23:X25)/AVERAGE($Z23:$Z25)) -> 2.2067153 | AD27: =1/(AVERAGE(Y23:Y25)/AVERAGE($Z23:$Z25)) -> 1.4718586
... B30: 46113 | C30: 46142 | D30: 26년 4월 | E30: =SUMIFS('전체 일별'!$BA:$BA,'전체 일별'!$B:$B,">="&$B30,'전체 일별'!$B:$B,"<="&$C30) -> 1757436603 | F30: =SUMIFS('전체 일별'!$L:$L,'전체 일별'!$B:$B,">="&$B30,'전체 일별'!$B:$B,"<="&$C30) -> 453033127 | G30: =SUMIFS('전체 일별'!$O:$O,'전체 일별'!$B:$B,">="&$B30,'전체 일별'!$B:$B,"<="&$C30) -> 57937 | H30: =SUMIFS('전체 일별'!$AQ:$AQ,'전체 일별'!$B:$B,">="&$B30,'전체 일별'!$B:$B,"<="&$C30) -> 42054 | I30: =SUMIFS('전체 일별'!$AR:$AR,'전체 일별'!$B:$B,">="&$B30,'전체 일별'!$B:$B,"<="&$C30) -> 38970 | J30: =SUMIFS('전체 일별'!$AJ:$AJ,'전체 일별'!$B:$B,">="&$B30,'전체 일별'!$B:$B,"<="&$C30) -> 20328 | K30: =SUMIFS('전체 일별'!$Z:$Z,'전체 일별'!$B:$B,">="&$B30,'전체 일별'!$B:$B,"<="&$C30) -> 14221 | L30: =SUMIFS('전체 일별'!$AL:$AL,'전체 일별'!$B:$B,">="&$B30,'전체 일별'!$B:$B,"<="&$C30) -> 183181 | M30: =SUMIFS('전체 일별'!$AO:$AO,'전체 일별'!$B:$B,">="&$B30,'전체 일별'!$B:$B,"<="&$C30) -> 135931 | N30: =SUMIFS('전체 일별'!$AP:$AP,'전체 일별'!$B:$B,">="&$B30,'전체 일별'!$B:$B,"<="&$C30) -> 3709 | O30: =F30/J30 -> 22286.163 | P30: =IFERROR(F30/K30,0) -> 31856.629 | Q30: =I30/H30 -> 0.92666572 | R30: =J30/I30 -> 0.52163202 | S30: =K30/I30 -> 0.36492173 | T30: =IFERROR(N30/(M30+N30),0) -> 0.026561157 | U30: =IFERROR(E30/M30,0) -> 12928.887 | V30: =AVERAGEIFS('전체 일별'!$AF:$AF,'전체 일별'!$B:$B,">="&$B30,'전체 일별'!$B:$B,"<="&$C30) -> 0.07929 | W30: =AVERAGEIFS('전체 일별'!$AB:$AB,'전체 일별'!$B:$B,">="&$B30,'전체 일별'!$B:$B,"<="&$C30) -> 0.13647 | X30: =AVERAGEIFS('전체 일별'!$X:$X,'전체 일별'!$B:$B,">="&$B30,'전체 일별'!$B:$B,"<="&$C30) -> 0.16559667 | Y30: =AVERAGEIFS('전체 일별'!$BG:$BG,'전체 일별'!$B:$B,">="&$B30,'전체 일별'!$B:$B,"<="&$C30) -> 0.21340667 | Z30: =AVERAGEIFS('전체 일별'!$BI:$BI,'전체 일별'!$B:$B,">="&$B30,'전체 일별'!$B:$B,"<="&$C30) -> 0.013316667 | AA30: =1/(AVERAGE(V26:V28)/AVERAGE($Z26:$Z28)) -> 4.313458 | AB30: =1/(AVERAGE(W26:W28)/AVERAGE($Z26:$Z28)) -> 2.7329057 | AC30: =1/(AVERAGE(X26:X28)/AVERAGE($Z26:$Z28)) -> 2.2106203 | AD30: =1/(AVERAGE(Y26:Y28)/AVERAGE($Z26:$Z28)) -> 1.4645593
D31: 전월대비 | E31: =E29-E28 -> 331856735 | F31: =F29-F28 -> 157300052 | G31: =G29-G28 -> 17954 | H31: =H29-H28 -> 14762 | I31: =I29-I28 -> 13590 | J31: =J29-J28 -> 5799 | K31: =K29-K28 -> 2781 | L31: =L29-L28 -> 21493 | ... U31: =U29-U28 -> -125.93671
D32: 전전월대비 | E32: =E29-E27 -> 399738346 | F32: =F29-F27 -> 165918704 | G32: =G29-G27 -> 23592 | H32: =H29-H27 -> 20200 | I32: =I29-I27 -> 17942 | J32: =J29-J27 -> 6736 | K32: =K29-K27 -> 4177 | L32: =L29-L27 -> 27450 | ... U32: =U29-U27 -> -158.65857

Sheet 전체 주별
B2: 부터 | C2: 까지 | D2: 주별 | E2: B2C 매출 | F2: 총 광고비 | G2: 메타 P_CPA | H2: ASA P_CPA | I2: X P_CPA | J2: 구글 P_CPA | K2: GFA | L2: SA | M2: 틱톡 P_CPA | N2: 가입자 수 | O2: 지역 내 가입자 수 | P2: 신규 유저 | Q2: 신규 유저(D30) | R2: B2C 총 신청 수 | S2: B2C 수거 완료 | T2: B2C 수거 실패 | U2: CAC | V2: P_CAC(보정값) | W2: 지역내 가입율 | X2: 서비스 이용 전환율 | Y2: 수거 실패율 | Z2: 객단가 | AA2: 회원탈퇴수 | AB2: 메타 PU | AC2: ASA PU | AD2: 구글 PU | AE2: 트위터 | AF2: GFA | AG2: SA | AH2: 틱톡 PU | AI2: 부터 | AJ2: 까지 | AK2: 최근 7일 d7의 평균 | AL2: 최근 7일 d30의 평균 | AM2: 기존 Paid 비율 | AN2: 보정된 Paid 비율 | AO2: 보정 계수 | AP2: Unattributed | AQ2: Paid로 귀속시킬 비율
B3: 45438 | C3: 45444 | D3: 24년 5월 4주차 | E3: =SUMIFS('전체 일별'!$BA:$BA,'전체 일별'!$B:$B,">="&$B3,'전체 일별'!$B:$B,"<="&$C3) -> 14907026 | F3: =SUMIFS('전체 일별'!$L:$L,'전체 일별'!$B:$B,">="&$B3,'전체 일별'!$B:$B,"<="&$C3) -> 4453808 | G3: 0 | I3: 0 | N3: =SUMIFS('전체 일별'!$AQ:$AQ,'전체 일별'!$B:$B,">="&$B3,'전체 일별'!$B:$B,"<="&$C3) -> 1582 | O3: =SUMIFS('전체 일별'!$AR:$AR,'전체 일별'!$B:$B,">="&$B3,'전체 일별'!$B:$B,"<="&$C3) -> 812 | P3: =SUMIFS('전체 일별'!$AJ:$AJ,'전체 일별'!$B:$B,">="&$B3,'전체 일별'!$B:$B,"<="&$C3) -> 289 | R3: =SUMIFS('전체 일별'!$AL:$AL,'전체 일별'!$B:$B,">="&$B3,'전체 일별'!$B:$B,"<="&$C3) -> 1927 | S3: =SUMIFS('전체 일별'!$AO:$AO,'전체 일별'!$B:$B,">="&$B3,'전체 일별'!$B:$B,"<="&$C3) -> 1697 | T3: =SUMIFS('전체 일별'!$AP:$AP,'전체 일별'!$B:$B,">="&$B3,'전체 일별'!$B:$B,"<="&$C3) -> 89 | U3: =F3/P3 -> 15411.1 | W3: =O3/N3 -> 0.51327434 | X3: =P3/O3 -> 0.35591133 | Y3: =T3/(S3+T3) -> 0.049832027 | Z3: =E3/S3 -> 8784.3406 | AB3: 0 | AM3: 0 | AN3: 0
B4: 45445 | C4: 45451 | D4: 24년 6월 1주차 | E4: =SUMIFS('전체 일별'!$BA:$BA,'전체 일별'!$B:$B,">="&$B4,'전체 일별'!$B:$B,"<="&$C4) -> 15528788 | F4: =SUMIFS('전체 일별'!$L:$L,'전체 일별'!$B:$B,">="&$B4,'전체 일별'!$B:$B,"<="&$C4) -> 3865264 | G4: 0 | I4: 140 | N4: =SUMIFS('전체 일별'!$AQ:$AQ,'전체 일별'!$B:$B,">="&$B4,'전체 일별'!$B:$B,"<="&$C4) -> 1455 | O4: =SUMIFS('전체 일별'!$AR:$AR,'전체 일별'!$B:$B,">="&$B4,'전체 일별'!$B:$B,"<="&$C4) -> 832 | P4: =SUMIFS('전체 일별'!$AJ:$AJ,'전체 일별'!$B:$B,">="&$B4,'전체 일별'!$B:$B,"<="&$C4) -> 305 | R4: =SUMIFS('전체 일별'!$AL:$AL,'전체 일별'!$B:$B,">="&$B4,'전체 일별'!$B:$B,"<="&$C4) -> 2118 | S4: =SUMIFS('전체 일별'!$AO:$AO,'전체 일별'!$B:$B,">="&$B4,'전체 일별'!$B:$B,"<="&$C4) -> 1918 | T4: =SUMIFS('전체 일별'!$AP:$AP,'전체 일별'!$B:$B,">="&$B4,'전체 일별'!$B:$B,"<="&$C4) -> 77 | U4: =F4/P4 -> 12672.997 | W4: =O4/N4 -> 0.57182131 | X4: =P4/O4 -> 0.36658654 | Y4: =T4/(S4+T4) -> 0.038596491 | Z4: =E4/S4 -> 8096.3441 | AB4: 0 | AM4: 0 | AN4: 0
B5: 45452 | C5: 45458 | D5: 24년 6월 2주차 | E5: =SUMIFS('전체 일별'!$BA:$BA,'전체 일별'!$B:$B,">="&$B5,'전체 일별'!$B:$B,"<="&$C5) -> 17971394 | F5: =SUMIFS('전체 일별'!$L:$L,'전체 일별'!$B:$B,">="&$B5,'전체 일별'!$B:$B,"<="&$C5) -> 3918473 | G5: 0 | I5: 126 | N5: =SUMIFS('전체 일별'!$AQ:$AQ,'전체 일별'!$B:$B,">="&$B5,'전체 일별'!$B:$B,"<="&$C5) -> 1361 | O5: =SUMIFS('전체 일별'!$AR:$AR,'전체 일별'!$B:$B,">="&$B5,'전체 일별'!$B:$B,"<="&$C5) -> 1009 | P5: =SUMIFS('전체 일별'!$AJ:$AJ,'전체 일별'!$B:$B,">="&$B5,'전체 일별'!$B:$B,"<="&$C5) -> 315 | R5: =SUMIFS('전체 일별'!$AL:$AL,'전체 일별'!$B:$B,">="&$B5,'전체 일별'!$B:$B,"<="&$C5) -> 2312 | S5: =SUMIFS('전체 일별'!$AO:$AO,'전체 일별'!$B:$B,">="&$B5,'전체 일별'!$B:$B,"<="&$C5) -> 2093 | T5: =SUMIFS('전체 일별'!$AP:$AP,'전체 일별'!$B:$B,">="&$B5,'전체 일별'!$B:$B,"<="&$C5) -> 81 | U5: =F5/P5 -> 12439.597 | W5: =O5/N5 -> 0.74136664 | X5: =P5/O5 -> 0.31219029 | Y5: =T5/(S5+T5) -> 0.03725851 | Z5: =E5/S5 -> 8586.4281 | AB5: 0 | AM5: 0 | AN5: 0
B6: 45459 | C6: 45465 | D6: 24년 6월 4주차 | E6: =SUMIFS('전체 일별'!$BA:$BA,'전체 일별'!$B:$B,">="&$B6,'전체 일별'!$B:$B,"<="&$C6) -> 18187604 | F6: =SUMIFS('전체 일별'!$L:$L,'전체 일별'!$B:$B,">="&$B6,'전체 일별'!$B:$B,"<="&$C6) -> 4585570 | G6: 0 | I6: 145 | N6: =SUMIFS('전체 일별'!$AQ:$AQ,'전체 일별'!$B:$B,">="&$B6,'전체 일별'!$B:$B,"<="&$C6) -> 1494 | O6: =SUMIFS('전체 일별'!$AR:$AR,'전체 일별'!$B:$B,">="&$B6,'전체 일별'!$B:$B,"<="&$C6) -> 1171 | P6: =SUMIFS('전체 일별'!$AJ:$AJ,'전체 일별'!$B:$B,">="&$B6,'전체 일별'!$B:$B,"<="&$C6) -> 335 | R6: =SUMIFS('전체 일별'!$AL:$AL,'전체 일별'!$B:$B,">="&$B6,'전체 일별'!$B:$B,"<="&$C6) -> 2377 | S6: =SUMIFS('전체 일별'!$AO:$AO,'전체 일별'!$B:$B,">="&$B6,'전체 일별'!$B:$B,"<="&$C6) -> 2162 | T6: =SUMIFS('전체 일별'!$AP:$AP,'전체 일별'!$B:$B,">="&$B6,'전체 일별'!$B:$B,"<="&$C6) -> 89 | U6: =F6/P6 -> 13688.269 | W6: =O6/N6 -> 0.78380187 | X6: =P6/O6 -> 0.28608027 | Y6: =T6/(S6+T6) -> 0.039537983 | Z6: =E6/S6 -> 8412.3978 | AB6: 0 | AM6: 0 | AN6: 0
B7: 45466 | C7: 45472 | D7: 24년 6월 5주차 | E7: =SUMIFS('전체 일별'!$BA:$BA,'전체 일별'!$B:$B,">="&$B7,'전체 일별'!$B:$B,"<="&$C7) -> 18466500 | F7: =SUMIFS('전체 일별'!$L:$L,'전체 일별'!$B:$B,">="&$B7,'전체 일별'!$B:$B,"<="&$C7) -> 4805841 | G7: 9193 | I7: 131 | N7: =SUMIFS('전체 일별'!$AQ:$AQ,'전체 일별'!$B:$B,">="&$B7,'전체 일별'!$B:$B,"<="&$C7) -> 1439 | O7: =SUMIFS('전체 일별'!$AR:$AR,'전체 일별'!$B:$B,">="&$B7,'전체 일별'!$B:$B,"<="&$C7) -> 1121 | P7: =SUMIFS('전체 일별'!$AJ:$AJ,'전체 일별'!$B:$B,">="&$B7,'전체 일별'!$B:$B,"<="&$C7) -> 341 | R7: =SUMIFS('전체 일별'!$AL:$AL,'전체 일별'!$B:$B,">="&$B7,'전체 일별'!$B:$B,"<="&$C7) -> 2461 | S7: =SUMIFS('전체 일별'!$AO:$AO,'전체 일별'!$B:$B,">="&$B7,'전체 일별'!$B:$B,"<="&$C7) -> 2153 | T7: =SUMIFS('전체 일별'!$AP:$AP,'전체 일별'!$B:$B,">="&$B7,'전체 일별'!$B:$B,"<="&$C7) -> 93 | U7: =F7/P7 -> 14093.375 | W7: =O7/N7 -> 0.7790132 | X7: =P7/O7 -> 0.30419269 | Y7: =T7/(S7+T7) -> 0.041406946 | Z7: =E7/S7 -> 8577.1017 | AB7: 9193 | AM7: 0 | AN7: 0
B8: =C7+1 -> 45473 | C8: =B8+6 -> 45479 | D8: 24년 7월 1주차 | E8: =SUMIFS('전체 일별'!$BA:$BA,'전체 일별'!$B:$B,">="&$B8,'전체 일별'!$B:$B,"<="&$C8) -> 19684866 | F8: =SUMIFS('전체 일별'!$L:$L,'전체 일별'!$B:$B,">="&$B8,'전체 일별'!$B:$B,"<="&$C8) -> 4385735 | G8: 4650.2 | I8: 116 | N8: =SUMIFS('전체 일별'!$AQ:$AQ,'전체 일별'!$B:$B,">="&$B8,'전체 일별'!$B:$B,"<="&$C8) -> 1390 | O8: =SUMIFS('전체 일별'!$AR:$AR,'전체 일별'!$B:$B,">="&$B8,'전체 일별'!$B:$B,"<="&$C8) -> 961 | P8: =SUMIFS('전체 일별'!$AJ:$AJ,'전체 일별'!$B:$B,">="&$B8,'전체 일별'!$B:$B,"<="&$C8) -> 315 | R8: =SUMIFS('전체 일별'!$AL:$AL,'전체 일별'!$B:$B,">="&$B8,'전체 일별'!$B:$B,"<="&$C8) -> 2613 | S8: =SUMIFS('전체 일별'!$AO:$AO,'전체 일별'!$B:$B,">="&$B8,'전체 일별'!$B:$B,"<="&$C8) -> 2382 | T8: =SUMIFS('전체 일별'!$AP:$AP,'전체 일별'!$B:$B,">="&$B8,'전체 일별'!$B:$B,"<="&$C8) -> 87 | U8: =F8/P8 -> 13922.968 | W8: =O8/N8 -> 0.69136691 | X8: =P8/O8 -> 0.32778356 | Y8: =T8/(S8+T8) -> 0.035236938 | Z8: =E8/S8 -> 8264.0076 | AB8: 4650.2 | AM8: 0 | AN8: 0
B9: =C8+1 -> 45480 | C9: =B9+6 -> 45486 | D9: 24년 7월 1주차 | E9: =SUMIFS('전체 일별'!$BA:$BA,'전체 일별'!$B:$B,">="&$B9,'전체 일별'!$B:$B,"<="&$C9) -> 20840256 | F9: =SUMIFS('전체 일별'!$L:$L,'전체 일별'!$B:$B,">="&$B9,'전체 일별'!$B:$B,"<="&$C9) -> 5535321 | G9: 4101.6 | I9: 117 | N9: =SUMIFS('전체 일별'!$AQ:$AQ,'전체 일별'!$B:$B,">="&$B9,'전체 일별'!$B:$B,"<="&$C9) -> 1581 | O9: =SUMIFS('전체 일별'!$AR:$AR,'전체 일별'!$B:$B,">="&$B9,'전체 일별'!$B:$B,"<="&$C9) -> 1206 | P9: =SUMIFS('전체 일별'!$AJ:$AJ,'전체 일별'!$B:$B,">="&$B9,'전체 일별'!$B:$B,"<="&$C9) -> 356 | R9: =SUMIFS('전체 일별'!$AL:$AL,'전체 일별'!$B:$B,">="&$B9,'전체 일별'!$B:$B,"<="&$C9) -> 2715 | S9: =SUMIFS('전체 일별'!$AO:$AO,'전체 일별'!$B:$B,">="&$B9,'전체 일별'!$B:$B,"<="&$C9) -> 2539 | T9: =SUMIFS('전체 일별'!$AP:$AP,'전체 일별'!$B:$B,">="&$B9,'전체 일별'!$B:$B,"<="&$C9) -> 64 | U9: =F9/P9 -> 15548.654 | W9: =O9/N9 -> 0.76280835 | X9: =P9/O9 -> 0.29519071 | Y9: =T9/(S9+T9) -> 0.024587015 | Z9: =E9/S9 -> 8208.0567 | AB9: 4101.6 | AM9: 0 | AN9: 0
B10: =C9+1 -> 45487 | C10: =B10+6 -> 45493 | D10: 24년 7월 1주차 | E10: =SUMIFS('전체 일별'!$BA:$BA,'전체 일별'!$B:$B,">="&$B10,'전체 일별'!$B:$B,"<="&$C10) -> 21471040 | F10: =SUMIFS('전체 일별'!$L:$L,'전체 일별'!$B:$B,">="&$B10,'전체 일별'!$B:$B,"<="&$C10) -> 5326054 | G10: 4101.6 | I10: 117 | N10: =SUMIFS('전체 일별'!$AQ:$AQ,'전체 일별'!$B:$B,">="&$B10,'전체 일별'!$B:$B,"<="&$C10) -> 1587 | O10: =SUMIFS('전체 일별'!$AR:$AR,'전체 일별'!$B:$B,">="&$B10,'전체 일별'!$B:$B,"<="&$C10) -> 1301 | P10: =SUMIFS('전체 일별'!$AJ:$AJ,'전체 일별'!$B:$B,">="&$B10,'전체 일별'!$B:$B,"<="&$C10) -> 389 | R10: =SUMIFS('전체 일별'!$AL:$AL,'전체 일별'!$B:$B,">="&$B10,'전체 일별'!$B:$B,"<="&$C10) -> 2874 | S10: =SUMIFS('전체 일별'!$AO:$AO,'전체 일별'!$B:$B,">="&$B10,'전체 일별'!$B:$B,"<="&$C10) -> 2684 | T10: =SUMIFS('전체 일별'!$AP:$AP,'전체 일별'!$B:$B,">="&$B10,'전체 일별'!$B:$B,"<="&$C10) -> 78 | U10: =F10/P10 -> 13691.656 | W10: =O10/N10 -> 0.81978576 | X10: =P10/O10 -> 0.29900077 | Y10: =T10/(S10+T10) -> 0.028240406 | Z10: =E10/S10 -> 7999.6423 | AB10: 4101.6 | AM10: 0 | AN10: 0
B11: 45492 | C11: =B11+6 -> 45498 | D11: 24년 7월 3주차 | E11: =SUMIFS('전체 일별'!$BA:$BA,'전체 일별'!$B:$B,">="&$B11,'전체 일별'!$B:$B,"<="&$C11) -> 24579906 | F11: =SUMIFS('전체 일별'!$L:$L,'전체 일별'!$B:$B,">="&$B11,'전체 일별'!$B:$B,"<="&$C11) -> 5273736 | G11: 4606.8434 | I11: 101.90965 | J11: 0 | N11: =SUMIFS('전체 일별'!$AQ:$AQ,'전체 일별'!$B:$B,">="&$B11,'전체 일별'!$B:$B,"<="&$C11) -> 1764 | O11: =SUMIFS('전체 일별'!$AR:$AR,'전체 일별'!$B:$B,">="&$B11,'전체 일별'!$B:$B,"<="&$C11) -> 1333 | P11: =SUMIFS('전체 일별'!$AJ:$AJ,'전체 일별'!$B:$B,">="&$B11,'전체 일별'!$B:$B,"<="&$C11) -> 470 | Q11: =SUMIFS('전체 일별'!$Z:$Z,'전체 일별'!$B:$B,">="&$B11,'전체 일별'!$B:$B,"<="&$C11) -> 424 | R11: =SUMIFS('전체 일별'!$AL:$AL,'전체 일별'!$B:$B,">="&$B11,'전체 일별'!$B:$B,"<="&$C11) -> 3074 | S11: =SUMIFS('전체 일별'!$AO:$AO,'전체 일별'!$B:$B,">="&$B11,'전체 일별'!$B:$B,"<="&$C11) -> 2856 | T11: =SUMIFS('전체 일별'!$AP:$AP,'전체 일별'!$B:$B,">="&$B11,'전체 일별'!$B:$B,"<="&$C11) -> 101 | U11: =F11/Q11 -> 12438.057 | W11: =O11/N11 -> 0.75566893 | X11: =Q11/O11 -> 0.31807952 | Y11: =T11/(S11+T11) -> 0.034156239 | Z11: =E11/S11 -> 8606.4097 | AB11: 4606.8434 | AD11: 0 | AM11: 0 | AN11: 0
B12: 45499 | C12: =B12+6 -> 45505 | D12: 24년 7월 5주차 | E12: =SUMIFS('전체 일별'!$BA:$BA,'전체 일별'!$B:$B,">="&$B12,'전체 일별'!$B:$B,"<="&$C12) -> 28467952 | F12: =SUMIFS('전체 일별'!$L:$L,'전체 일별'!$B:$B,">="&$B12,'전체 일별'!$B:$B,"<="&$C12) -> 6660898 | G12: 5143.6792 | I12: 102.04489 | J12: 0 | N12: =SUMIFS('전체 일별'!$AQ:$AQ,'전체 일별'!$B:$B,">="&$B12,'전체 일별'!$B:$B,"<="&$C12) -> 1913 | O12: =SUMIFS('전체 일별'!$AR:$AR,'전체 일별'!$B:$B,">="&$B12,'전체 일별'!$B:$B,"<="&$C12) -> 1595 | P12: =SUMIFS('전체 일별'!$AJ:$AJ,'전체 일별'!$B:$B,">="&$B12,'전체 일별'!$B:$B,"<="&$C12) -> 572 | Q12: =SUMIFS('전체 일별'!$Z:$Z,'전체 일별'!$B:$B,">="&$B12,'전체 일별'!$B:$B,"<="&$C12) -> 472 | R12: =SUMIFS('전체 일별'!$AL:$AL,'전체 일별'!$B:$B,">="&$B12,'전체 일별'!$B:$B,"<="&$C12) -> 3443 | S12: =SUMIFS('전체 일별'!$AO:$AO,'전체 일별'!$B:$B,">="&$B12,'전체 일별'!$B:$B,"<="&$C12) -> 3219 | T12: =SUMIFS('전체 일별'!$AP:$AP,'전체 일별'!$B:$B,">="&$B12,'전체 일별'!$B:$B,"<="&$C12) -> 98 | U12: =F12/Q12 -> 14112.072 | W12: =O12/N12 -> 0.83376895 | X12: =Q12/O12 -> 0.29592476 | Y12: =T12/(S12+T12) -> 0.029544769 | Z12: =E12/S12 -> 8843.7254 | AB12: 5143.6792 | AD12: 0 | AM12: 0 | AN12: 0
B13: 45506 | C13: =B13+6 -> 45512 | D13: 24년 8월 1주차 | E13: =SUMIFS('전체 일별'!$BA:$BA,'전체 일별'!$B:$B,">="&$B13,'전체 일별'!$B:$B,"<="&$C13) -> 28439832 | F13: =SUMIFS('전체 일별'!$L:$L,'전체 일별'!$B:$B,">="&$B13,'전체 일별'!$B:$B,"<="&$C13) -> 7076897 | G13: 5904.4856 | I13: 96.287251 | J13: 0 | N13: =SUMIFS('전체 일별'!$AQ:$AQ,'전체 일별'!$B:$B,">="&$B13,'전체 일별'!$B:$B,"<="&$C13) -> 2025 | O13: =SUMIFS('전체 일별'!$AR:$AR,'전체 일별'!$B:$B,">="&$B13,'전체 일별'!$B:$B,"<="&$C13) -> 1647 | P13: =SUMIFS('전체 일별'!$AJ:$AJ,'전체 일별'!$B:$B,">="&$B13,'전체 일별'!$B:$B,"<="&$C13) -> 574 | Q13: =SUMIFS('전체 일별'!$Z:$Z,'전체 일별'!$B:$B,">="&$B13,'전체 일별'!$B:$B,"<="&$C13) -> 447 | R13: =SUMIFS('전체 일별'!$AL:$AL,'전체 일별'!$B:$B,">="&$B13,'전체 일별'!$B:$B,"<="&$C13) -> 3508 | S13: =SUMIFS('전체 일별'!$AO:$AO,'전체 일별'!$B:$B,">="&$B13,'전체 일별'!$B:$B,"<="&$C13) -> 3261 | T13: =SUMIFS('전체 일별'!$AP:$AP,'전체 일별'!$B:$B,">="&$B13,'전체 일별'!$B:$B,"<="&$C13) -> 120 | U13: =F13/Q13 -> 15831.984 | W13: =O13/N13 -> 0.81333333 | X13: =Q13/O13 -> 0.27140255 | Y13: =T13/(S13+T13) -> 0.035492458 | Z13: =E13/S13 -> 8721.1996 | AB13: 5904.4856 | AD13: 0 | AM13: 0 | AN13: 0
B14: 45513 | C14: 45519 | D14: 24년 8월 2주차 | E14: =SUMIFS('전체 일별'!$BA:$BA,'전체 일별'!$B:$B,">="&$B14,'전체 일별'!$B:$B,"<="&$C14) -> 29431882 | F14: =SUMIFS('전체 일별'!$L:$L,'전체 일별'!$B:$B,">="&$B14,'전체 일별'!$B:$B,"<="&$C14) -> 5578535 | G14: 6250 | I14: 106.75859 | J14: 0 | N14: =SUMIFS('전체 일별'!$AQ:$AQ,'전체 일별'!$B:$B,">="&$B14,'전체 일별'!$B:$B,"<="&$C14) -> 1823 | O14: =SUMIFS('전체 일별'!$AR:$AR,'전체 일별'!$B:$B,">="&$B14,'전체 일별'!$B:$B,"<="&$C14) -> 1512 | P14: =SUMIFS('전체 일별'!$AJ:$AJ,'전체 일별'!$B:$B,">="&$B14,'전체 일별'!$B:$B,"<="&$C14) -> 554 | Q14: =SUMIFS('전체 일별'!$Z:$Z,'전체 일별'!$B:$B,">="&$B14,'전체 일별'!$B:$B,"<="&$C14) -> 425 | R14: =SUMIFS('전체 일별'!$AL:$AL,'전체 일별'!$B:$B,">="&$B14,'전체 일별'!$B:$B,"<="&$C14) -> 3755 | S14: =SUMIFS('전체 일별'!$AO:$AO,'전체 일별'!$B:$B,">="&$B14,'전체 일별'!$B:$B,"<="&$C14) -> 3432 | T14: =SUMIFS('전체 일별'!$AP:$AP,'전체 일별'!$B:$B,">="&$B14,'전체 일별'!$B:$B,"<="&$C14) -> 118 | U14: =F14/Q14 -> 13125.965 | W14: =O14/N14 -> 0.82940208 | X14: =Q14/O14 -> 0.28108466 | Y14: =T14/(S14+T14) -> 0.033239437 | Z14: =E14/S14 -> 8575.7232 | AB14: 6250 | AD14: 0 | AM14: 0 | AN14: 0
